Workbook

Sheet Cripto
A1: Janeiro | B1: 1
A2: Fevereiro | B2: 2
A3: Março | B3: 3
A4: Abril | B4: 4
A5: Maio | B5: 5
A6: Junho | B6: 6
A7: Julho | B7: 7
A8: Agosto | B8: 8
A9: Setembro | B9: 9
A10: Outubro | B10: 10
A11: Novembro | B11: 11
A12: Dezembro | B12: 12

Sheet Mensal
A1: Saldo da conta em 01 de Janeiro: | D1: 9523.69 | E1: =D1+E3+E103-E122 -> 9758.92 | F1: =E1+F3+F103-F122 -> 8085.88 | G1: =F1+G3+G103-G122 -> 9530.62 | H1: =G1+H3+H103-H122 -> 9591.21 | I1: =H1+I3+I103-I122 -> 10488.8 | J1: =I1+J3+J103-J122 -> 10968.92 | K1: =J1+K3+K103-K122 -> 11112.46 | L1: =K1+L3+L103-L122 -> 11772.46 | ... P1: =O1+P3+P103-P122 -> 11772.46
C2: Mensalidade | E2: Janeiro | F2: Fevereiro | G2: Março | H2: Abril | I2: Maio | J2: Junho | K2: Julho | L2: Agosto | M2: Setembro | N2: Outubro | O2: Novembro | P2: Dezembro | S2: =MONTH(TODAY())*20 -> 160
B3: Inativo | C3: Total mensal: | E3: =SUM(E4:E100) -> 320 | F3: =SUM(F4:F100) -> 1300 | G3: =SUM(G4:G100) -> 2280 | H3: =SUM(H4:H100) -> 660 | I3: =SUM(I4:I100) -> 920 | J3: =SUM(J4:J100) -> 1440 | K3: =SUM(K4:K100) -> 620 | L3: =SUM(L4:L100) -> 660 | ... P3: =SUM(P4:P100) -> 0 | Q3: PRIMEIRO PAGAMENTO DO ANO | R3: ATRASO | S3: GRÁFICO
B4: {=IFERROR(INDEX(#REF!,MATCH(C4,#REF!,0)),"")} | C4: =IFERROR(__xludf.DUMMYFUNCTION("QUERY('Cadastro de Sócios 2026'!A2:V170,""SELECT C, D WHERE U = TRUE"",1)"),"Angélica") -> Angélica | D4: =IFERROR(__xludf.DUMMYFUNCTION("""COMPUTED_VALUE"""),"Angélica Mateus") -> Angélica Mateus | E4: =SUMIFS(Pagamentos!$E:$E,Pagamentos!$F:$F,TRUE,Pagamentos!$C:$C,$C4,Pagamentos!$D:$D,E$2) -> 0 | F4: =SUMIFS(Pagamentos!$E:$E,Pagamentos!$F:$F,TRUE,Pagamentos!$C:$C,$C4,Pagamentos!$D:$D,F$2) -> 40 | G4: =SUMIFS(Pagamentos!$E:$E,Pagamentos!$F:$F,TRUE,Pagamentos!$C:$C,$C4,Pagamentos!$D:$D,G$2) -> 20 | H4: =SUMIFS(Pagamentos!$E:$E,Pagamentos!$F:$F,TRUE,Pagamentos!$C:$C,$C4,Pagamentos!$D:$D,H$2) -> 0 | I4: =SUMIFS(Pagamentos!$E:$E,Pagamentos!$F:$F,TRUE,Pagamentos!$C:$C,$C4,Pagamentos!$D:$D,I$2) -> 40 | J4: =SUMIFS(Pagamentos!$E:$E,Pagamentos!$F:$F,TRUE,Pagamentos!$C:$C,$C4,Pagamentos!$D:$D,J$2) -> 20 | K4: =SUMIFS(Pagamentos!$E:$E,Pagamentos!$F:$F,TRUE,Pagamentos!$C:$C,$C4,Pagamentos!$D:$D,K$2) -> 0 | L4: =SUMIFS(Pagamentos!$E:$E,Pagamentos!$F:$F,TRUE,Pagamentos!$C:$C,$C4,Pagamentos!$D:$D,L$2) -> 0 | ... P4: =SUMIFS(Pagamentos!$E:$E,Pagamentos!$F:$F,TRUE,Pagamentos!$C:$C,$C4,Pagamentos!$D:$D,P$2) -> 0 | Q4: 0 | R4: =IF(Q4="","",((SUM(E4:P4)-$S$2)/20)+Q4) -> -2 | S4: =IFERROR(__xludf.DUMMYFUNCTION("SPARKLINE(SUM(E4:P4),{""charttype"",""bar"";""max"",$S$2})"),"")
B5: {=IFERROR(INDEX(#REF!,MATCH(C5,#REF!,0)),"")} | C5: =IFERROR(__xludf.DUMMYFUNCTION("""COMPUTED_VALUE"""),"Antunes") -> Antunes | D5: =IFERROR(__xludf.DUMMYFUNCTION("""COMPUTED_VALUE"""),"Douglas Antunes") -> Douglas Antunes | E5: =SUMIFS(Pagamentos!$E:$E,Pagamentos!$F:$F,TRUE,Pagamentos!$C:$C,$C5,Pagamentos!$D:$D,E$2) -> 20 | F5: =SUMIFS(Pagamentos!$E:$E,Pagamentos!$F:$F,TRUE,Pagamentos!$C:$C,$C5,Pagamentos!$D:$D,F$2) -> 20 | G5: =SUMIFS(Pagamentos!$E:$E,Pagamentos!$F:$F,TRUE,Pagamentos!$C:$C,$C5,Pagamentos!$D:$D,G$2) -> 20 | H5: =SUMIFS(Pagamentos!$E:$E,Pagamentos!$F:$F,TRUE,Pagamentos!$C:$C,$C5,Pagamentos!$D:$D,H$2) -> 0 | I5: =SUMIFS(Pagamentos!$E:$E,Pagamentos!$F:$F,TRUE,Pagamentos!$C:$C,$C5,Pagamentos!$D:$D,I$2) -> 40 | J5: =SUMIFS(Pagamentos!$E:$E,Pagamentos!$F:$F,TRUE,Pagamentos!$C:$C,$C5,Pagamentos!$D:$D,J$2) -> 20 | K5: =SUMIFS(Pagamentos!$E:$E,Pagamentos!$F:$F,TRUE,Pagamentos!$C:$C,$C5,Pagamentos!$D:$D,K$2) -> 20 | L5: =SUMIFS(Pagamentos!$E:$E,Pagamentos!$F:$F,TRUE,Pagamentos!$C:$C,$C5,Pagamentos!$D:$D,L$2) -> 0 | ... P5: =SUMIFS(Pagamentos!$E:$E,Pagamentos!$F:$F,TRUE,Pagamentos!$C:$C,$C5,Pagamentos!$D:$D,P$2) -> 0 | Q5: 0 | R5: =IF(Q5="","",((SUM(E5:P5)-$S$2)/20)+Q5) -> -1 | S5: =IFERROR(__xludf.DUMMYFUNCTION("SPARKLINE(SUM(E5:P5),{""charttype"",""bar"";""max"",$S$2})"),"")
B6: {=IFERROR(INDEX(#REF!,MATCH(C6,#REF!,0)),"")} | C6: =IFERROR(__xludf.DUMMYFUNCTION("""COMPUTED_VALUE"""),"Augusto") -> Augusto | D6: =IFERROR(__xludf.DUMMYFUNCTION("""COMPUTED_VALUE"""),"Murilo Augusto Galdino De Souza") -> Murilo Augusto Galdino De Souza | E6: =SUMIFS(Pagamentos!$E:$E,Pagamentos!$F:$F,TRUE,Pagamentos!$C:$C,$C6,Pagamentos!$D:$D,E$2) -> 20 | F6: =SUMIFS(Pagamentos!$E:$E,Pagamentos!$F:$F,TRUE,Pagamentos!$C:$C,$C6,Pagamentos!$D:$D,F$2) -> 20 | G6: =SUMIFS(Pagamentos!$E:$E,Pagamentos!$F:$F,TRUE,Pagamentos!$C:$C,$C6,Pagamentos!$D:$D,G$2) -> 20 | H6: =SUMIFS(Pagamentos!$E:$E,Pagamentos!$F:$F,TRUE,Pagamentos!$C:$C,$C6,Pagamentos!$D:$D,H$2) -> 20 | I6: =SUMIFS(Pagamentos!$E:$E,Pagamentos!$F:$F,TRUE,Pagamentos!$C:$C,$C6,Pagamentos!$D:$D,I$2) -> 20 | J6: =SUMIFS(Pagamentos!$E:$E,Pagamentos!$F:$F,TRUE,Pagamentos!$C:$C,$C6,Pagamentos!$D:$D,J$2) -> 20 | K6: =SUMIFS(Pagamentos!$E:$E,Pagamentos!$F:$F,TRUE,Pagamentos!$C:$C,$C6,Pagamentos!$D:$D,K$2) -> 0 | L6: =SUMIFS(Pagamentos!$E:$E,Pagamentos!$F:$F,TRUE,Pagamentos!$C:$C,$C6,Pagamentos!$D:$D,L$2) -> 20 | ... P6: =SUMIFS(Pagamentos!$E:$E,Pagamentos!$F:$F,TRUE,Pagamentos!$C:$C,$C6,Pagamentos!$D:$D,P$2) -> 0 | Q6: 0 | R6: =IF(Q6="","",((SUM(E6:P6)-$S$2)/20)+Q6) -> -1 | S6: =IFERROR(__xludf.DUMMYFUNCTION("SPARKLINE(SUM(E6:P6),{""charttype"",""bar"";""max"",$S$2})"),"")
B7: {=IFERROR(INDEX(#REF!,MATCH(C7,#REF!,0)),"")} | C7: =IFERROR(__xludf.DUMMYFUNCTION("""COMPUTED_VALUE"""),"Andreia") -> Andreia | D7: =IFERROR(__xludf.DUMMYFUNCTION("""COMPUTED_VALUE"""),"Andreia de Fátima Machado ") -> Andreia de Fátima Machado | E7: =SUMIFS(Pagamentos!$E:$E,Pagamentos!$F:$F,TRUE,Pagamentos!$C:$C,$C7,Pagamentos!$D:$D,E$2) -> 0 | F7: =SUMIFS(Pagamentos!$E:$E,Pagamentos!$F:$F,TRUE,Pagamentos!$C:$C,$C7,Pagamentos!$D:$D,F$2) -> 0 | G7: =SUMIFS(Pagamentos!$E:$E,Pagamentos!$F:$F,TRUE,Pagamentos!$C:$C,$C7,Pagamentos!$D:$D,G$2) -> 80 | H7: =SUMIFS(Pagamentos!$E:$E,Pagamentos!$F:$F,TRUE,Pagamentos!$C:$C,$C7,Pagamentos!$D:$D,H$2) -> 0 | I7: =SUMIFS(Pagamentos!$E:$E,Pagamentos!$F:$F,TRUE,Pagamentos!$C:$C,$C7,Pagamentos!$D:$D,I$2) -> 0 | J7: =SUMIFS(Pagamentos!$E:$E,Pagamentos!$F:$F,TRUE,Pagamentos!$C:$C,$C7,Pagamentos!$D:$D,J$2) -> 0 | K7: =SUMIFS(Pagamentos!$E:$E,Pagamentos!$F:$F,TRUE,Pagamentos!$C:$C,$C7,Pagamentos!$D:$D,K$2) -> 0 | L7: =SUMIFS(Pagamentos!$E:$E,Pagamentos!$F:$F,TRUE,Pagamentos!$C:$C,$C7,Pagamentos!$D:$D,L$2) -> 80 | ... P7: =SUMIFS(Pagamentos!$E:$E,Pagamentos!$F:$F,TRUE,Pagamentos!$C:$C,$C7,Pagamentos!$D:$D,P$2) -> 0 | Q7: 0 | R7: =IF(Q7="","",((SUM(E7:P7)-$S$2)/20)+Q7) -> 0 | S7: =IFERROR(__xludf.DUMMYFUNCTION("SPARKLINE(SUM(E7:P7),{""charttype"",""bar"";""max"",$S$2})"),"")
B8: {=IFERROR(INDEX(#REF!,MATCH(C8,#REF!,0)),"")} | C8: =IFERROR(__xludf.DUMMYFUNCTION("""COMPUTED_VALUE"""),"Bento") -> Bento | D8: =IFERROR(__xludf.DUMMYFUNCTION("""COMPUTED_VALUE"""),"Daniel Bento") -> Daniel Bento | E8: =SUMIFS(Pagamentos!$E:$E,Pagamentos!$F:$F,TRUE,Pagamentos!$C:$C,$C8,Pagamentos!$D:$D,E$2) -> 0 | F8: =SUMIFS(Pagamentos!$E:$E,Pagamentos!$F:$F,TRUE,Pagamentos!$C:$C,$C8,Pagamentos!$D:$D,F$2) -> 0 | G8: =SUMIFS(Pagamentos!$E:$E,Pagamentos!$F:$F,TRUE,Pagamentos!$C:$C,$C8,Pagamentos!$D:$D,G$2) -> 20 | H8: =SUMIFS(Pagamentos!$E:$E,Pagamentos!$F:$F,TRUE,Pagamentos!$C:$C,$C8,Pagamentos!$D:$D,H$2) -> 0 | I8: =SUMIFS(Pagamentos!$E:$E,Pagamentos!$F:$F,TRUE,Pagamentos!$C:$C,$C8,Pagamentos!$D:$D,I$2) -> 20 | J8: =SUMIFS(Pagamentos!$E:$E,Pagamentos!$F:$F,TRUE,Pagamentos!$C:$C,$C8,Pagamentos!$D:$D,J$2) -> 20 | K8: =SUMIFS(Pagamentos!$E:$E,Pagamentos!$F:$F,TRUE,Pagamentos!$C:$C,$C8,Pagamentos!$D:$D,K$2) -> 20 | L8: =SUMIFS(Pagamentos!$E:$E,Pagamentos!$F:$F,TRUE,Pagamentos!$C:$C,$C8,Pagamentos!$D:$D,L$2) -> 0 | ... P8: =SUMIFS(Pagamentos!$E:$E,Pagamentos!$F:$F,TRUE,Pagamentos!$C:$C,$C8,Pagamentos!$D:$D,P$2) -> 0 | Q8: 2 | R8: =IF(Q8="","",((SUM(E8:P8)-$S$2)/20)+Q8) -> -2 | S8: =IFERROR(__xludf.DUMMYFUNCTION("SPARKLINE(SUM(E8:P8),{""charttype"",""bar"";""max"",$S$2})"),"")
B9: {=IFERROR(INDEX(#REF!,MATCH(C9,#REF!,0)),"")} | C9: =IFERROR(__xludf.DUMMYFUNCTION("""COMPUTED_VALUE"""),"Binhoti") -> Binhoti | D9: =IFERROR(__xludf.DUMMYFUNCTION("""COMPUTED_VALUE"""),"Tiago Binhoti") -> Tiago Binhoti | E9: =SUMIFS(Pagamentos!$E:$E,Pagamentos!$F:$F,TRUE,Pagamentos!$C:$C,$C9,Pagamentos!$D:$D,E$2) -> 0 | F9: =SUMIFS(Pagamentos!$E:$E,Pagamentos!$F:$F,TRUE,Pagamentos!$C:$C,$C9,Pagamentos!$D:$D,F$2) -> 120 | G9: =SUMIFS(Pagamentos!$E:$E,Pagamentos!$F:$F,TRUE,Pagamentos!$C:$C,$C9,Pagamentos!$D:$D,G$2) -> 0 | H9: =SUMIFS(Pagamentos!$E:$E,Pagamentos!$F:$F,TRUE,Pagamentos!$C:$C,$C9,Pagamentos!$D:$D,H$2) -> 0 | I9: =SUMIFS(Pagamentos!$E:$E,Pagamentos!$F:$F,TRUE,Pagamentos!$C:$C,$C9,Pagamentos!$D:$D,I$2) -> 0 | J9: =SUMIFS(Pagamentos!$E:$E,Pagamentos!$F:$F,TRUE,Pagamentos!$C:$C,$C9,Pagamentos!$D:$D,J$2) -> 0 | K9: =SUMIFS(Pagamentos!$E:$E,Pagamentos!$F:$F,TRUE,Pagamentos!$C:$C,$C9,Pagamentos!$D:$D,K$2) -> 0 | L9: =SUMIFS(Pagamentos!$E:$E,Pagamentos!$F:$F,TRUE,Pagamentos!$C:$C,$C9,Pagamentos!$D:$D,L$2) -> 120 | ... P9: =SUMIFS(Pagamentos!$E:$E,Pagamentos!$F:$F,TRUE,Pagamentos!$C:$C,$C9,Pagamentos!$D:$D,P$2) -> 0 | Q9: 1 | R9: =IF(Q9="","",((SUM(E9:P9)-$S$2)/20)+Q9) -> 5 | S9: =IFERROR(__xludf.DUMMYFUNCTION("SPARKLINE(SUM(E9:P9),{""charttype"",""bar"";""max"",$S$2})"),"")
B10: {=IFERROR(INDEX(#REF!,MATCH(C10,#REF!,0)),"")} | C10: =IFERROR(__xludf.DUMMYFUNCTION("""COMPUTED_VALUE"""),"Boiko") -> Boiko | D10: =IFERROR(__xludf.DUMMYFUNCTION("""COMPUTED_VALUE"""),"Emerson Roberto Boiko") -> Emerson Roberto Boiko | E10: =SUMIFS(Pagamentos!$E:$E,Pagamentos!$F:$F,TRUE,Pagamentos!$C:$C,$C10,Pagamentos!$D:$D,E$2) -> 0 | F10: =SUMIFS(Pagamentos!$E:$E,Pagamentos!$F:$F,TRUE,Pagamentos!$C:$C,$C10,Pagamentos!$D:$D,F$2) -> 0 | G10: =SUMIFS(Pagamentos!$E:$E,Pagamentos!$F:$F,TRUE,Pagamentos!$C:$C,$C10,Pagamentos!$D:$D,G$2) -> 100 | H10: =SUMIFS(Pagamentos!$E:$E,Pagamentos!$F:$F,TRUE,Pagamentos!$C:$C,$C10,Pagamentos!$D:$D,H$2) -> 0 | I10: =SUMIFS(Pagamentos!$E:$E,Pagamentos!$F:$F,TRUE,Pagamentos!$C:$C,$C10,Pagamentos!$D:$D,I$2) -> 0 | J10: =SUMIFS(Pagamentos!$E:$E,Pagamentos!$F:$F,TRUE,Pagamentos!$C:$C,$C10,Pagamentos!$D:$D,J$2) -> 60 | K10: =SUMIFS(Pagamentos!$E:$E,Pagamentos!$F:$F,TRUE,Pagamentos!$C:$C,$C10,Pagamentos!$D:$D,K$2) -> 0 | L10: =SUMIFS(Pagamentos!$E:$E,Pagamentos!$F:$F,TRUE,Pagamentos!$C:$C,$C10,Pagamentos!$D:$D,L$2) -> 0 | ... P10: =SUMIFS(Pagamentos!$E:$E,Pagamentos!$F:$F,TRUE,Pagamentos!$C:$C,$C10,Pagamentos!$D:$D,P$2) -> 0 | Q10: -2 | R10: =IF(Q10="","",((SUM(E10:P10)-$S$2)/20)+Q10) -> -2 | S10: =IFERROR(__xludf.DUMMYFUNCTION("SPARKLINE(SUM(E10:P10),{""charttype"",""bar"";""max"",$S$2})"),"")
B11: {=IFERROR(INDEX(#REF!,MATCH(C11,#REF!,0)),"")} | C11: =IFERROR(__xludf.DUMMYFUNCTION("""COMPUTED_VALUE"""),"Camila") -> Camila | D11: =IFERROR(__xludf.DUMMYFUNCTION("""COMPUTED_VALUE"""),"Camila Coelho Soares") -> Camila Coelho Soares | E11: =SUMIFS(Pagamentos!$E:$E,Pagamentos!$F:$F,TRUE,Pagamentos!$C:$C,$C11,Pagamentos!$D:$D,E$2) -> 20 | F11: =SUMIFS(Pagamentos!$E:$E,Pagamentos!$F:$F,TRUE,Pagamentos!$C:$C,$C11,Pagamentos!$D:$D,F$2) -> 20 | G11: =SUMIFS(Pagamentos!$E:$E,Pagamentos!$F:$F,TRUE,Pagamentos!$C:$C,$C11,Pagamentos!$D:$D,G$2) -> 20 | H11: =SUMIFS(Pagamentos!$E:$E,Pagamentos!$F:$F,TRUE,Pagamentos!$C:$C,$C11,Pagamentos!$D:$D,H$2) -> 20 | I11: =SUMIFS(Pagamentos!$E:$E,Pagamentos!$F:$F,TRUE,Pagamentos!$C:$C,$C11,Pagamentos!$D:$D,I$2) -> 20 | J11: =SUMIFS(Pagamentos!$E:$E,Pagamentos!$F:$F,TRUE,Pagamentos!$C:$C,$C11,Pagamentos!$D:$D,J$2) -> 20 | K11: =SUMIFS(Pagamentos!$E:$E,Pagamentos!$F:$F,TRUE,Pagamentos!$C:$C,$C11,Pagamentos!$D:$D,K$2) -> 20 | L11: =SUMIFS(Pagamentos!$E:$E,Pagamentos!$F:$F,TRUE,Pagamentos!$C:$C,$C11,Pagamentos!$D:$D,L$2) -> 0 | ... P11: =SUMIFS(Pagamentos!$E:$E,Pagamentos!$F:$F,TRUE,Pagamentos!$C:$C,$C11,Pagamentos!$D:$D,P$2) -> 0 | Q11: 0 | R11: =IF(Q11="","",((SUM(E11:P11)-$S$2)/20)+Q11) -> -1 | S11: =IFERROR(__xludf.DUMMYFUNCTION("SPARKLINE(SUM(E11:P11),{""charttype"",""bar"";""max"",$S$2})"),"")
B12: {=IFERROR(INDEX(#REF!,MATCH(C12,#REF!,0)),"")} | C12: =IFERROR(__xludf.DUMMYFUNCTION("""COMPUTED_VALUE"""),"Coelho") -> Coelho | D12: =IFERROR(__xludf.DUMMYFUNCTION("""COMPUTED_VALUE"""),"Ricardo Augusto Coelho") -> Ricardo Augusto Coelho | E12: =SUMIFS(Pagamentos!$E:$E,Pagamentos!$F:$F,TRUE,Pagamentos!$C:$C,$C12,Pagamentos!$D:$D,E$2) -> 0 | F12: =SUMIFS(Pagamentos!$E:$E,Pagamentos!$F:$F,TRUE,Pagamentos!$C:$C,$C12,Pagamentos!$D:$D,F$2) -> 0 | G12: =SUMIFS(Pagamentos!$E:$E,Pagamentos!$F:$F,TRUE,Pagamentos!$C:$C,$C12,Pagamentos!$D:$D,G$2) -> 60 | H12: =SUMIFS(Pagamentos!$E:$E,Pagamentos!$F:$F,TRUE,Pagamentos!$C:$C,$C12,Pagamentos!$D:$D,H$2) -> 60 | I12: =SUMIFS(Pagamentos!$E:$E,Pagamentos!$F:$F,TRUE,Pagamentos!$C:$C,$C12,Pagamentos!$D:$D,I$2) -> 0 | J12: =SUMIFS(Pagamentos!$E:$E,Pagamentos!$F:$F,TRUE,Pagamentos!$C:$C,$C12,Pagamentos!$D:$D,J$2) -> 0 | K12: =SUMIFS(Pagamentos!$E:$E,Pagamentos!$F:$F,TRUE,Pagamentos!$C:$C,$C12,Pagamentos!$D:$D,K$2) -> 0 | L12: =SUMIFS(Pagamentos!$E:$E,Pagamentos!$F:$F,TRUE,Pagamentos!$C:$C,$C12,Pagamentos!$D:$D,L$2) -> 80 | ... P12: =SUMIFS(Pagamentos!$E:$E,Pagamentos!$F:$F,TRUE,Pagamentos!$C:$C,$C12,Pagamentos!$D:$D,P$2) -> 0 | Q12: 0 | R12: =IF(Q12="","",((SUM(E12:P12)-$S$2)/20)+Q12) -> 2 | S12: =IFERROR(__xludf.DUMMYFUNCTION("SPARKLINE(SUM(E12:P12),{""charttype"",""bar"";""max"",$S$2})"),"")
B13: {=IFERROR(INDEX(#REF!,MATCH(C13,#REF!,0)),"")} | C13: =IFERROR(__xludf.DUMMYFUNCTION("""COMPUTED_VALUE"""),"Da Silva") -> Da Silva | D13: =IFERROR(__xludf.DUMMYFUNCTION("""COMPUTED_VALUE"""),"Alex Sandro Batista da Silva") -> Alex Sandro Batista da Silva | E13: =SUMIFS(Pagamentos!$E:$E,Pagamentos!$F:$F,TRUE,Pagamentos!$C:$C,$C13,Pagamentos!$D:$D,E$2) -> 0 | F13: =SUMIFS(Pagamentos!$E:$E,Pagamentos!$F:$F,TRUE,Pagamentos!$C:$C,$C13,Pagamentos!$D:$D,F$2) -> 0 | G13: =SUMIFS(Pagamentos!$E:$E,Pagamentos!$F:$F,TRUE,Pagamentos!$C:$C,$C13,Pagamentos!$D:$D,G$2) -> 0 | H13: =SUMIFS(Pagamentos!$E:$E,Pagamentos!$F:$F,TRUE,Pagamentos!$C:$C,$C13,Pagamentos!$D:$D,H$2) -> 0 | I13: =SUMIFS(Pagamentos!$E:$E,Pagamentos!$F:$F,TRUE,Pagamentos!$C:$C,$C13,Pagamentos!$D:$D,I$2) -> 0 | J13: =SUMIFS(Pagamentos!$E:$E,Pagamentos!$F:$F,TRUE,Pagamentos!$C:$C,$C13,Pagamentos!$D:$D,J$2) -> 0 | K13: =SUMIFS(Pagamentos!$E:$E,Pagamentos!$F:$F,TRUE,Pagamentos!$C:$C,$C13,Pagamentos!$D:$D,K$2) -> 0 | L13: =SUMIFS(Pagamentos!$E:$E,Pagamentos!$F:$F,TRUE,Pagamentos!$C:$C,$C13,Pagamentos!$D:$D,L$2) -> 0 | ... P13: =SUMIFS(Pagamentos!$E:$E,Pagamentos!$F:$F,TRUE,Pagamentos!$C:$C,$C13,Pagamentos!$D:$D,P$2) -> 0 | Q13: 12 | R13: =IF(Q13="","",((SUM(E13:P13)-$S$2)/20)+Q13) -> 4 | S13: =IFERROR(__xludf.DUMMYFUNCTION("SPARKLINE(SUM(E13:P13),{""charttype"",""bar"";""max"",$S$2})"),"")
B14: {=IFERROR(INDEX(#REF!,MATCH(C14,#REF!,0)),"")} | C14: =IFERROR(__xludf.DUMMYFUNCTION("""COMPUTED_VALUE"""),"Barros") -> Barros | D14: =IFERROR(__xludf.DUMMYFUNCTION("""COMPUTED_VALUE"""),"Michel da Silveira Barros ") -> Michel da Silveira Barros | E14: =SUMIFS(Pagamentos!$E:$E,Pagamentos!$F:$F,TRUE,Pagamentos!$C:$C,$C14,Pagamentos!$D:$D,E$2) -> 0 | F14: =SUMIFS(Pagamentos!$E:$E,Pagamentos!$F:$F,TRUE,Pagamentos!$C:$C,$C14,Pagamentos!$D:$D,F$2) -> 20 | G14: =SUMIFS(Pagamentos!$E:$E,Pagamentos!$F:$F,TRUE,Pagamentos!$C:$C,$C14,Pagamentos!$D:$D,G$2) -> 40 | H14: =SUMIFS(Pagamentos!$E:$E,Pagamentos!$F:$F,TRUE,Pagamentos!$C:$C,$C14,Pagamentos!$D:$D,H$2) -> 0 | I14: =SUMIFS(Pagamentos!$E:$E,Pagamentos!$F:$F,TRUE,Pagamentos!$C:$C,$C14,Pagamentos!$D:$D,I$2) -> 0 | J14: =SUMIFS(Pagamentos!$E:$E,Pagamentos!$F:$F,TRUE,Pagamentos!$C:$C,$C14,Pagamentos!$D:$D,J$2) -> 60 | K14: =SUMIFS(Pagamentos!$E:$E,Pagamentos!$F:$F,TRUE,Pagamentos!$C:$C,$C14,Pagamentos!$D:$D,K$2) -> 0 | L14: =SUMIFS(Pagamentos!$E:$E,Pagamentos!$F:$F,TRUE,Pagamentos!$C:$C,$C14,Pagamentos!$D:$D,L$2) -> 0 | ... P14: =SUMIFS(Pagamentos!$E:$E,Pagamentos!$F:$F,TRUE,Pagamentos!$C:$C,$C14,Pagamentos!$D:$D,P$2) -> 0 | Q14: 0 | R14: =IF(Q14="","",((SUM(E14:P14)-$S$2)/20)+Q14) -> -2 | S14: =IFERROR(__xludf.DUMMYFUNCTION("SPARKLINE(SUM(E14:P14),{""charttype"",""bar"";""max"",$S$2})"),"")
B15: {=IFERROR(INDEX(#REF!,MATCH(C15,#REF!,0)),"")} | C15: =IFERROR(__xludf.DUMMYFUNCTION("""COMPUTED_VALUE"""),"Deny") -> Deny | D15: =IFERROR(__xludf.DUMMYFUNCTION("""COMPUTED_VALUE"""),"Deny Anderson Azevedo ") -> Deny Anderson Azevedo | E15: =SUMIFS(Pagamentos!$E:$E,Pagamentos!$F:$F,TRUE,Pagamentos!$C:$C,$C15,Pagamentos!$D:$D,E$2) -> 0 | F15: =SUMIFS(Pagamentos!$E:$E,Pagamentos!$F:$F,TRUE,Pagamentos!$C:$C,$C15,Pagamentos!$D:$D,F$2) -> 0 | G15: =SUMIFS(Pagamentos!$E:$E,Pagamentos!$F:$F,TRUE,Pagamentos!$C:$C,$C15,Pagamentos!$D:$D,G$2) -> 0 | H15: =SUMIFS(Pagamentos!$E:$E,Pagamentos!$F:$F,TRUE,Pagamentos!$C:$C,$C15,Pagamentos!$D:$D,H$2) -> 0 | I15: =SUMIFS(Pagamentos!$E:$E,Pagamentos!$F:$F,TRUE,Pagamentos!$C:$C,$C15,Pagamentos!$D:$D,I$2) -> 0 | J15: =SUMIFS(Pagamentos!$E:$E,Pagamentos!$F:$F,TRUE,Pagamentos!$C:$C,$C15,Pagamentos!$D:$D,J$2) -> 60 | K15: =SUMIFS(Pagamentos!$E:$E,Pagamentos!$F:$F,TRUE,Pagamentos!$C:$C,$C15,Pagamentos!$D:$D,K$2) -> 0 | L15: =SUMIFS(Pagamentos!$E:$E,Pagamentos!$F:$F,TRUE,Pagamentos!$C:$C,$C15,Pagamentos!$D:$D,L$2) -> 0 | ... P15: =SUMIFS(Pagamentos!$E:$E,Pagamentos!$F:$F,TRUE,Pagamentos!$C:$C,$C15,Pagamentos!$D:$D,P$2) -> 0 | Q15: 3 | R15: =IF(Q15="","",((SUM(E15:P15)-$S$2)/20)+Q15) -> -2 | S15: =IFERROR(__xludf.DUMMYFUNCTION("SPARKLINE(SUM(E15:P15),{""charttype"",""bar"";""max"",$S$2})"),"")
B16: {=IFERROR(INDEX(#REF!,MATCH(C16,#REF!,0)),"")} | C16: =IFERROR(__xludf.DUMMYFUNCTION("""COMPUTED_VALUE"""),"Eder") -> Eder | D16: =IFERROR(__xludf.DUMMYFUNCTION("""COMPUTED_VALUE"""),"Eder Alison Da Silva") -> Eder Alison Da Silva | E16: =SUMIFS(Pagamentos!$E:$E,Pagamentos!$F:$F,TRUE,Pagamentos!$C:$C,$C16,Pagamentos!$D:$D,E$2) -> 0 | F16: =SUMIFS(Pagamentos!$E:$E,Pagamentos!$F:$F,TRUE,Pagamentos!$C:$C,$C16,Pagamentos!$D:$D,F$2) -> 0 | G16: =SUMIFS(Pagamentos!$E:$E,Pagamentos!$F:$F,TRUE,Pagamentos!$C:$C,$C16,Pagamentos!$D:$D,G$2) -> 0 | H16: =SUMIFS(Pagamentos!$E:$E,Pagamentos!$F:$F,TRUE,Pagamentos!$C:$C,$C16,Pagamentos!$D:$D,H$2) -> 100 | I16: =SUMIFS(Pagamentos!$E:$E,Pagamentos!$F:$F,TRUE,Pagamentos!$C:$C,$C16,Pagamentos!$D:$D,I$2) -> 0 | J16: =SUMIFS(Pagamentos!$E:$E,Pagamentos!$F:$F,TRUE,Pagamentos!$C:$C,$C16,Pagamentos!$D:$D,J$2) -> 40 | K16: =SUMIFS(Pagamentos!$E:$E,Pagamentos!$F:$F,TRUE,Pagamentos!$C:$C,$C16,Pagamentos!$D:$D,K$2) -> 0 | L16: =SUMIFS(Pagamentos!$E:$E,Pagamentos!$F:$F,TRUE,Pagamentos!$C:$C,$C16,Pagamentos!$D:$D,L$2) -> 0 | ... P16: =SUMIFS(Pagamentos!$E:$E,Pagamentos!$F:$F,TRUE,Pagamentos!$C:$C,$C16,Pagamentos!$D:$D,P$2) -> 0 | Q16: -1 | R16: =IF(Q16="","",((SUM(E16:P16)-$S$2)/20)+Q16) -> -2 | S16: =IFERROR(__xludf.DUMMYFUNCTION("SPARKLINE(SUM(E16:P16),{""charttype"",""bar"";""max"",$S$2})"),"")
B17: {=IFERROR(INDEX(#REF!,MATCH(C17,#REF!,0)),"")} | C17: =IFERROR(__xludf.DUMMYFUNCTION("""COMPUTED_VALUE"""),"Elaine") -> Elaine | D17: =IFERROR(__xludf.DUMMYFUNCTION("""COMPUTED_VALUE"""),"Elaine Conrado Bittencourt ") -> Elaine Conrado Bittencourt | E17: =SUMIFS(Pagamentos!$E:$E,Pagamentos!$F:$F,TRUE,Pagamentos!$C:$C,$C17,Pagamentos!$D:$D,E$2) -> 0 | F17: =SUMIFS(Pagamentos!$E:$E,Pagamentos!$F:$F,TRUE,Pagamentos!$C:$C,$C17,Pagamentos!$D:$D,F$2) -> 40 | G17: =SUMIFS(Pagamentos!$E:$E,Pagamentos!$F:$F,TRUE,Pagamentos!$C:$C,$C17,Pagamentos!$D:$D,G$2) -> 20 | H17: =SUMIFS(Pagamentos!$E:$E,Pagamentos!$F:$F,TRUE,Pagamentos!$C:$C,$C17,Pagamentos!$D:$D,H$2) -> 0 | I17: =SUMIFS(Pagamentos!$E:$E,Pagamentos!$F:$F,TRUE,Pagamentos!$C:$C,$C17,Pagamentos!$D:$D,I$2) -> 20 | J17: =SUMIFS(Pagamentos!$E:$E,Pagamentos!$F:$F,TRUE,Pagamentos!$C:$C,$C17,Pagamentos!$D:$D,J$2) -> 60 | K17: =SUMIFS(Pagamentos!$E:$E,Pagamentos!$F:$F,TRUE,Pagamentos!$C:$C,$C17,Pagamentos!$D:$D,K$2) -> 0 | L17: =SUMIFS(Pagamentos!$E:$E,Pagamentos!$F:$F,TRUE,Pagamentos!$C:$C,$C17,Pagamentos!$D:$D,L$2) -> 0 | ... P17: =SUMIFS(Pagamentos!$E:$E,Pagamentos!$F:$F,TRUE,Pagamentos!$C:$C,$C17,Pagamentos!$D:$D,P$2) -> 0 | Q17: 0 | R17: =IF(Q17="","",((SUM(E17:P17)-$S$2)/20)+Q17) -> -1 | S17: =IFERROR(__xludf.DUMMYFUNCTION("SPARKLINE(SUM(E17:P17),{""charttype"",""bar"";""max"",$S$2})"),"")
B18: {=IFERROR(INDEX(#REF!,MATCH(C18,#REF!,0)),"")} | C18: =IFERROR(__xludf.DUMMYFUNCTION("""COMPUTED_VALUE"""),"Fabiana") -> Fabiana | D18: =IFERROR(__xludf.DUMMYFUNCTION("""COMPUTED_VALUE"""),"Fabiana Oro Cericato Costa") -> Fabiana Oro Cericato Costa | E18: =SUMIFS(Pagamentos!$E:$E,Pagamentos!$F:$F,TRUE,Pagamentos!$C:$C,$C18,Pagamentos!$D:$D,E$2) -> 0 | F18: =SUMIFS(Pagamentos!$E:$E,Pagamentos!$F:$F,TRUE,Pagamentos!$C:$C,$C18,Pagamentos!$D:$D,F$2) -> 200 | G18: =SUMIFS(Pagamentos!$E:$E,Pagamentos!$F:$F,TRUE,Pagamentos!$C:$C,$C18,Pagamentos!$D:$D,G$2) -> 0 | H18: =SUMIFS(Pagamentos!$E:$E,Pagamentos!$F:$F,TRUE,Pagamentos!$C:$C,$C18,Pagamentos!$D:$D,H$2) -> 0 | I18: =SUMIFS(Pagamentos!$E:$E,Pagamentos!$F:$F,TRUE,Pagamentos!$C:$C,$C18,Pagamentos!$D:$D,I$2) -> 0 | J18: =SUMIFS(Pagamentos!$E:$E,Pagamentos!$F:$F,TRUE,Pagamentos!$C:$C,$C18,Pagamentos!$D:$D,J$2) -> 0 | K18: =SUMIFS(Pagamentos!$E:$E,Pagamentos!$F:$F,TRUE,Pagamentos!$C:$C,$C18,Pagamentos!$D:$D,K$2) -> 0 | L18: =SUMIFS(Pagamentos!$E:$E,Pagamentos!$F:$F,TRUE,Pagamentos!$C:$C,$C18,Pagamentos!$D:$D,L$2) -> 0 | ... P18: =SUMIFS(Pagamentos!$E:$E,Pagamentos!$F:$F,TRUE,Pagamentos!$C:$C,$C18,Pagamentos!$D:$D,P$2) -> 0 | Q18: 1 | R18: =IF(Q18="","",((SUM(E18:P18)-$S$2)/20)+Q18) -> 3 | S18: =IFERROR(__xludf.DUMMYFUNCTION("SPARKLINE(SUM(E18:P18),{""charttype"",""bar"";""max"",$S$2})"),"")
B19: {=IFERROR(INDEX(#REF!,MATCH(C19,#REF!,0)),"")} | C19: =IFERROR(__xludf.DUMMYFUNCTION("""COMPUTED_VALUE"""),"Gabriel") -> Gabriel | D19: =IFERROR(__xludf.DUMMYFUNCTION("""COMPUTED_VALUE"""),"Gabriel Francisco Farias da Silva") -> Gabriel Francisco Farias da Silva | E19: =SUMIFS(Pagamentos!$E:$E,Pagamentos!$F:$F,TRUE,Pagamentos!$C:$C,$C19,Pagamentos!$D:$D,E$2) -> 0 | F19: =SUMIFS(Pagamentos!$E:$E,Pagamentos!$F:$F,TRUE,Pagamentos!$C:$C,$C19,Pagamentos!$D:$D,F$2) -> 40 | G19: =SUMIFS(Pagamentos!$E:$E,Pagamentos!$F:$F,TRUE,Pagamentos!$C:$C,$C19,Pagamentos!$D:$D,G$2) -> 20 | H19: =SUMIFS(Pagamentos!$E:$E,Pagamentos!$F:$F,TRUE,Pagamentos!$C:$C,$C19,Pagamentos!$D:$D,H$2) -> 0 | I19: =SUMIFS(Pagamentos!$E:$E,Pagamentos!$F:$F,TRUE,Pagamentos!$C:$C,$C19,Pagamentos!$D:$D,I$2) -> 0 | J19: =SUMIFS(Pagamentos!$E:$E,Pagamentos!$F:$F,TRUE,Pagamentos!$C:$C,$C19,Pagamentos!$D:$D,J$2) -> 60 | K19: =SUMIFS(Pagamentos!$E:$E,Pagamentos!$F:$F,TRUE,Pagamentos!$C:$C,$C19,Pagamentos!$D:$D,K$2) -> 0 | L19: =SUMIFS(Pagamentos!$E:$E,Pagamentos!$F:$F,TRUE,Pagamentos!$C:$C,$C19,Pagamentos!$D:$D,L$2) -> 40 | ... P19: =SUMIFS(Pagamentos!$E:$E,Pagamentos!$F:$F,TRUE,Pagamentos!$C:$C,$C19,Pagamentos!$D:$D,P$2) -> 0 | Q19: 0 | R19: =IF(Q19="","",((SUM(E19:P19)-$S$2)/20)+Q19) -> 0 | S19: =IFERROR(__xludf.DUMMYFUNCTION("SPARKLINE(SUM(E19:P19),{""charttype"",""bar"";""max"",$S$2})"),"")
B20: {=IFERROR(INDEX(#REF!,MATCH(C20,#REF!,0)),"")} | C20: =IFERROR(__xludf.DUMMYFUNCTION("""COMPUTED_VALUE"""),"Henkes") -> Henkes | D20: =IFERROR(__xludf.DUMMYFUNCTION("""COMPUTED_VALUE"""),"Marcia Aparecida Henkes") -> Marcia Aparecida Henkes | E20: =SUMIFS(Pagamentos!$E:$E,Pagamentos!$F:$F,TRUE,Pagamentos!$C:$C,$C20,Pagamentos!$D:$D,E$2) -> 0 | F20: =SUMIFS(Pagamentos!$E:$E,Pagamentos!$F:$F,TRUE,Pagamentos!$C:$C,$C20,Pagamentos!$D:$D,F$2) -> 0 | G20: =SUMIFS(Pagamentos!$E:$E,Pagamentos!$F:$F,TRUE,Pagamentos!$C:$C,$C20,Pagamentos!$D:$D,G$2) -> 100 | H20: =SUMIFS(Pagamentos!$E:$E,Pagamentos!$F:$F,TRUE,Pagamentos!$C:$C,$C20,Pagamentos!$D:$D,H$2) -> 0 | I20: =SUMIFS(Pagamentos!$E:$E,Pagamentos!$F:$F,TRUE,Pagamentos!$C:$C,$C20,Pagamentos!$D:$D,I$2) -> 0 | J20: =SUMIFS(Pagamentos!$E:$E,Pagamentos!$F:$F,TRUE,Pagamentos!$C:$C,$C20,Pagamentos!$D:$D,J$2) -> 60 | K20: =SUMIFS(Pagamentos!$E:$E,Pagamentos!$F:$F,TRUE,Pagamentos!$C:$C,$C20,Pagamentos!$D:$D,K$2) -> 0 | L20: =SUMIFS(Pagamentos!$E:$E,Pagamentos!$F:$F,TRUE,Pagamentos!$C:$C,$C20,Pagamentos!$D:$D,L$2) -> 0 | ... P20: =SUMIFS(Pagamentos!$E:$E,Pagamentos!$F:$F,TRUE,Pagamentos!$C:$C,$C20,Pagamentos!$D:$D,P$2) -> 0 | Q20: -2 | R20: =IF(Q20="","",((SUM(E20:P20)-$S$2)/20)+Q20) -> -2 | S20: =IFERROR(__xludf.DUMMYFUNCTION("SPARKLINE(SUM(E20:P20),{""charttype"",""bar"";""max"",$S$2})"),"")
B21: {=IFERROR(INDEX(#REF!,MATCH(C21,#REF!,0)),"")} | C21: =IFERROR(__xludf.DUMMYFUNCTION("""COMPUTED_VALUE"""),"Humberto") -> Humberto | D21: =IFERROR(__xludf.DUMMYFUNCTION("""COMPUTED_VALUE"""),"Carlos Humberto luiz") -> Carlos Humberto luiz | E21: =SUMIFS(Pagamentos!$E:$E,Pagamentos!$F:$F,TRUE,Pagamentos!$C:$C,$C21,Pagamentos!$D:$D,E$2) -> 0 | F21: =SUMIFS(Pagamentos!$E:$E,Pagamentos!$F:$F,TRUE,Pagamentos!$C:$C,$C21,Pagamentos!$D:$D,F$2) -> 0 | G21: =SUMIFS(Pagamentos!$E:$E,Pagamentos!$F:$F,TRUE,Pagamentos!$C:$C,$C21,Pagamentos!$D:$D,G$2) -> 60 | H21: =SUMIFS(Pagamentos!$E:$E,Pagamentos!$F:$F,TRUE,Pagamentos!$C:$C,$C21,Pagamentos!$D:$D,H$2) -> 20 | I21: =SUMIFS(Pagamentos!$E:$E,Pagamentos!$F:$F,TRUE,Pagamentos!$C:$C,$C21,Pagamentos!$D:$D,I$2) -> 20 | J21: =SUMIFS(Pagamentos!$E:$E,Pagamentos!$F:$F,TRUE,Pagamentos!$C:$C,$C21,Pagamentos!$D:$D,J$2) -> 20 | K21: =SUMIFS(Pagamentos!$E:$E,Pagamentos!$F:$F,TRUE,Pagamentos!$C:$C,$C21,Pagamentos!$D:$D,K$2) -> 20 | L21: =SUMIFS(Pagamentos!$E:$E,Pagamentos!$F:$F,TRUE,Pagamentos!$C:$C,$C21,Pagamentos!$D:$D,L$2) -> 20 | ... P21: =SUMIFS(Pagamentos!$E:$E,Pagamentos!$F:$F,TRUE,Pagamentos!$C:$C,$C21,Pagamentos!$D:$D,P$2) -> 0 | Q21: 2 | R21: =IF(Q21="","",((SUM(E21:P21)-$S$2)/20)+Q21) -> 2 | S21: =IFERROR(__xludf.DUMMYFUNCTION("SPARKLINE(SUM(E21:P21),{""charttype"",""bar"";""max"",$S$2})"),"")
B22: {=IFERROR(INDEX(#REF!,MATCH(C22,#REF!,0)),"")} | C22: =IFERROR(__xludf.DUMMYFUNCTION("""COMPUTED_VALUE"""),"Ilton") -> Ilton | D22: =IFERROR(__xludf.DUMMYFUNCTION("""COMPUTED_VALUE"""),"Ilton Saturnino Braz") -> Ilton Saturnino Braz | E22: =SUMIFS(Pagamentos!$E:$E,Pagamentos!$F:$F,TRUE,Pagamentos!$C:$C,$C22,Pagamentos!$D:$D,E$2) -> 0 | F22: =SUMIFS(Pagamentos!$E:$E,Pagamentos!$F:$F,TRUE,Pagamentos!$C:$C,$C22,Pagamentos!$D:$D,F$2) -> 0 | G22: =SUMIFS(Pagamentos!$E:$E,Pagamentos!$F:$F,TRUE,Pagamentos!$C:$C,$C22,Pagamentos!$D:$D,G$2) -> 100 | H22: =SUMIFS(Pagamentos!$E:$E,Pagamentos!$F:$F,TRUE,Pagamentos!$C:$C,$C22,Pagamentos!$D:$D,H$2) -> 0 | I22: =SUMIFS(Pagamentos!$E:$E,Pagamentos!$F:$F,TRUE,Pagamentos!$C:$C,$C22,Pagamentos!$D:$D,I$2) -> 0 | J22: =SUMIFS(Pagamentos!$E:$E,Pagamentos!$F:$F,TRUE,Pagamentos!$C:$C,$C22,Pagamentos!$D:$D,J$2) -> 60 | K22: =SUMIFS(Pagamentos!$E:$E,Pagamentos!$F:$F,TRUE,Pagamentos!$C:$C,$C22,Pagamentos!$D:$D,K$2) -> 0 | L22: =SUMIFS(Pagamentos!$E:$E,Pagamentos!$F:$F,TRUE,Pagamentos!$C:$C,$C22,Pagamentos!$D:$D,L$2) -> 0 | ... P22: =SUMIFS(Pagamentos!$E:$E,Pagamentos!$F:$F,TRUE,Pagamentos!$C:$C,$C22,Pagamentos!$D:$D,P$2) -> 0 | Q22: -2 | R22: =IF(Q22="","",((SUM(E22:P22)-$S$2)/20)+Q22) -> -2 | S22: =IFERROR(__xludf.DUMMYFUNCTION("SPARKLINE(SUM(E22:P22),{""charttype"",""bar"";""max"",$S$2})"),"")
B23: {=IFERROR(INDEX(#REF!,MATCH(C23,#REF!,0)),"")} | C23: =IFERROR(__xludf.DUMMYFUNCTION("""COMPUTED_VALUE"""),"Kassandra") -> Kassandra | D23: =IFERROR(__xludf.DUMMYFUNCTION("""COMPUTED_VALUE"""),"Gabriela Kassandra Luiz Colossi") -> Gabriela Kassandra Luiz Colossi | E23: =SUMIFS(Pagamentos!$E:$E,Pagamentos!$F:$F,TRUE,Pagamentos!$C:$C,$C23,Pagamentos!$D:$D,E$2) -> 20 | F23: =SUMIFS(Pagamentos!$E:$E,Pagamentos!$F:$F,TRUE,Pagamentos!$C:$C,$C23,Pagamentos!$D:$D,F$2) -> 40 | G23: =SUMIFS(Pagamentos!$E:$E,Pagamentos!$F:$F,TRUE,Pagamentos!$C:$C,$C23,Pagamentos!$D:$D,G$2) -> 40 | H23: =SUMIFS(Pagamentos!$E:$E,Pagamentos!$F:$F,TRUE,Pagamentos!$C:$C,$C23,Pagamentos!$D:$D,H$2) -> 20 | I23: =SUMIFS(Pagamentos!$E:$E,Pagamentos!$F:$F,TRUE,Pagamentos!$C:$C,$C23,Pagamentos!$D:$D,I$2) -> 20 | J23: =SUMIFS(Pagamentos!$E:$E,Pagamentos!$F:$F,TRUE,Pagamentos!$C:$C,$C23,Pagamentos!$D:$D,J$2) -> 0 | K23: =SUMIFS(Pagamentos!$E:$E,Pagamentos!$F:$F,TRUE,Pagamentos!$C:$C,$C23,Pagamentos!$D:$D,K$2) -> 20 | L23: =SUMIFS(Pagamentos!$E:$E,Pagamentos!$F:$F,TRUE,Pagamentos!$C:$C,$C23,Pagamentos!$D:$D,L$2) -> 0 | ... P23: =SUMIFS(Pagamentos!$E:$E,Pagamentos!$F:$F,TRUE,Pagamentos!$C:$C,$C23,Pagamentos!$D:$D,P$2) -> 0 | Q23: 2 | R23: =IF(Q23="","",((SUM(E23:P23)-$S$2)/20)+Q23) -> 2 | S23: =IFERROR(__xludf.DUMMYFUNCTION("SPARKLINE(SUM(E23:P23),{""charttype"",""bar"";""max"",$S$2})"),"")
B24: {=IFERROR(INDEX(#REF!,MATCH(C24,#REF!,0)),"")} | C24: =IFERROR(__xludf.DUMMYFUNCTION("""COMPUTED_VALUE"""),"Linder") -> Linder | D24: =IFERROR(__xludf.DUMMYFUNCTION("""COMPUTED_VALUE"""),"Gustavo Augusto Linder") -> Gustavo Augusto Linder | E24: =SUMIFS(Pagamentos!$E:$E,Pagamentos!$F:$F,TRUE,Pagamentos!$C:$C,$C24,Pagamentos!$D:$D,E$2) -> 0 | F24: =SUMIFS(Pagamentos!$E:$E,Pagamentos!$F:$F,TRUE,Pagamentos!$C:$C,$C24,Pagamentos!$D:$D,F$2) -> 60 | G24: =SUMIFS(Pagamentos!$E:$E,Pagamentos!$F:$F,TRUE,Pagamentos!$C:$C,$C24,Pagamentos!$D:$D,G$2) -> 0 | H24: =SUMIFS(Pagamentos!$E:$E,Pagamentos!$F:$F,TRUE,Pagamentos!$C:$C,$C24,Pagamentos!$D:$D,H$2) -> 0 | I24: =SUMIFS(Pagamentos!$E:$E,Pagamentos!$F:$F,TRUE,Pagamentos!$C:$C,$C24,Pagamentos!$D:$D,I$2) -> 0 | J24: =SUMIFS(Pagamentos!$E:$E,Pagamentos!$F:$F,TRUE,Pagamentos!$C:$C,$C24,Pagamentos!$D:$D,J$2) -> 40 | K24: =SUMIFS(Pagamentos!$E:$E,Pagamentos!$F:$F,TRUE,Pagamentos!$C:$C,$C24,Pagamentos!$D:$D,K$2) -> 0 | L24: =SUMIFS(Pagamentos!$E:$E,Pagamentos!$F:$F,TRUE,Pagamentos!$C:$C,$C24,Pagamentos!$D:$D,L$2) -> 0 | ... P24: =SUMIFS(Pagamentos!$E:$E,Pagamentos!$F:$F,TRUE,Pagamentos!$C:$C,$C24,Pagamentos!$D:$D,P$2) -> 0 | Q24: 1 | R24: =IF(Q24="","",((SUM(E24:P24)-$S$2)/20)+Q24) -> -2 | S24: =IFERROR(__xludf.DUMMYFUNCTION("SPARKLINE(SUM(E24:P24),{""charttype"",""bar"";""max"",$S$2})"),"")
B25: {=IFERROR(INDEX(#REF!,MATCH(C25,#REF!,0)),"")} | C25: =IFERROR(__xludf.DUMMYFUNCTION("""COMPUTED_VALUE"""),"Lourenço") -> Lourenço | D25: =IFERROR(__xludf.DUMMYFUNCTION("""COMPUTED_VALUE"""),"Carlos Henrique Lourenço Gonçalves") -> Carlos Henrique Lourenço Gonçalves | E25: =SUMIFS(Pagamentos!$E:$E,Pagamentos!$F:$F,TRUE,Pagamentos!$C:$C,$C25,Pagamentos!$D:$D,E$2) -> 20 | F25: =SUMIFS(Pagamentos!$E:$E,Pagamentos!$F:$F,TRUE,Pagamentos!$C:$C,$C25,Pagamentos!$D:$D,F$2) -> 20 | G25: =SUMIFS(Pagamentos!$E:$E,Pagamentos!$F:$F,TRUE,Pagamentos!$C:$C,$C25,Pagamentos!$D:$D,G$2) -> 20 | H25: =SUMIFS(Pagamentos!$E:$E,Pagamentos!$F:$F,TRUE,Pagamentos!$C:$C,$C25,Pagamentos!$D:$D,H$2) -> 20 | I25: =SUMIFS(Pagamentos!$E:$E,Pagamentos!$F:$F,TRUE,Pagamentos!$C:$C,$C25,Pagamentos!$D:$D,I$2) -> 20 | J25: =SUMIFS(Pagamentos!$E:$E,Pagamentos!$F:$F,TRUE,Pagamentos!$C:$C,$C25,Pagamentos!$D:$D,J$2) -> 20 | K25: =SUMIFS(Pagamentos!$E:$E,Pagamentos!$F:$F,TRUE,Pagamentos!$C:$C,$C25,Pagamentos!$D:$D,K$2) -> 20 | L25: =SUMIFS(Pagamentos!$E:$E,Pagamentos!$F:$F,TRUE,Pagamentos!$C:$C,$C25,Pagamentos!$D:$D,L$2) -> 0 | ... P25: =SUMIFS(Pagamentos!$E:$E,Pagamentos!$F:$F,TRUE,Pagamentos!$C:$C,$C25,Pagamentos!$D:$D,P$2) -> 0 | Q25: -1 | R25: =IF(Q25="","",((SUM(E25:P25)-$S$2)/20)+Q25) -> -2 | S25: =IFERROR(__xludf.DUMMYFUNCTION("SPARKLINE(SUM(E25:P25),{""charttype"",""bar"";""max"",$S$2})"),"")
B26: {=IFERROR(INDEX(#REF!,MATCH(C26,#REF!,0)),"")} | C26: =IFERROR(__xludf.DUMMYFUNCTION("""COMPUTED_VALUE"""),"Lucas") -> Lucas | D26: =IFERROR(__xludf.DUMMYFUNCTION("""COMPUTED_VALUE"""),"Lucas Rodrigues Antônio ") -> Lucas Rodrigues Antônio | E26: =SUMIFS(Pagamentos!$E:$E,Pagamentos!$F:$F,TRUE,Pagamentos!$C:$C,$C26,Pagamentos!$D:$D,E$2) -> 0 | F26: =SUMIFS(Pagamentos!$E:$E,Pagamentos!$F:$F,TRUE,Pagamentos!$C:$C,$C26,Pagamentos!$D:$D,F$2) -> 0 | G26: =SUMIFS(Pagamentos!$E:$E,Pagamentos!$F:$F,TRUE,Pagamentos!$C:$C,$C26,Pagamentos!$D:$D,G$2) -> 100 | H26: =SUMIFS(Pagamentos!$E:$E,Pagamentos!$F:$F,TRUE,Pagamentos!$C:$C,$C26,Pagamentos!$D:$D,H$2) -> 0 | I26: =SUMIFS(Pagamentos!$E:$E,Pagamentos!$F:$F,TRUE,Pagamentos!$C:$C,$C26,Pagamentos!$D:$D,I$2) -> 0 | J26: =SUMIFS(Pagamentos!$E:$E,Pagamentos!$F:$F,TRUE,Pagamentos!$C:$C,$C26,Pagamentos!$D:$D,J$2) -> 0 | K26: =SUMIFS(Pagamentos!$E:$E,Pagamentos!$F:$F,TRUE,Pagamentos!$C:$C,$C26,Pagamentos!$D:$D,K$2) -> 0 | L26: =SUMIFS(Pagamentos!$E:$E,Pagamentos!$F:$F,TRUE,Pagamentos!$C:$C,$C26,Pagamentos!$D:$D,L$2) -> 100 | ... P26: =SUMIFS(Pagamentos!$E:$E,Pagamentos!$F:$F,TRUE,Pagamentos!$C:$C,$C26,Pagamentos!$D:$D,P$2) -> 0 | Q26: 2 | R26: =IF(Q26="","",((SUM(E26:P26)-$S$2)/20)+Q26) -> 4 | S26: =IFERROR(__xludf.DUMMYFUNCTION("SPARKLINE(SUM(E26:P26),{""charttype"",""bar"";""max"",$S$2})"),"")
B27: {=IFERROR(INDEX(#REF!,MATCH(C27,#REF!,0)),"")} | C27: =IFERROR(__xludf.DUMMYFUNCTION("""COMPUTED_VALUE"""),"Mayara") -> Mayara | D27: =IFERROR(__xludf.DUMMYFUNCTION("""COMPUTED_VALUE"""),"Mayara Vieira Soares") -> Mayara Vieira Soares | E27: =SUMIFS(Pagamentos!$E:$E,Pagamentos!$F:$F,TRUE,Pagamentos!$C:$C,$C27,Pagamentos!$D:$D,E$2) -> 0 | F27: =SUMIFS(Pagamentos!$E:$E,Pagamentos!$F:$F,TRUE,Pagamentos!$C:$C,$C27,Pagamentos!$D:$D,F$2) -> 0 | G27: =SUMIFS(Pagamentos!$E:$E,Pagamentos!$F:$F,TRUE,Pagamentos!$C:$C,$C27,Pagamentos!$D:$D,G$2) -> 120 | H27: =SUMIFS(Pagamentos!$E:$E,Pagamentos!$F:$F,TRUE,Pagamentos!$C:$C,$C27,Pagamentos!$D:$D,H$2) -> 0 | I27: =SUMIFS(Pagamentos!$E:$E,Pagamentos!$F:$F,TRUE,Pagamentos!$C:$C,$C27,Pagamentos!$D:$D,I$2) -> 0 | J27: =SUMIFS(Pagamentos!$E:$E,Pagamentos!$F:$F,TRUE,Pagamentos!$C:$C,$C27,Pagamentos!$D:$D,J$2) -> 0 | K27: =SUMIFS(Pagamentos!$E:$E,Pagamentos!$F:$F,TRUE,Pagamentos!$C:$C,$C27,Pagamentos!$D:$D,K$2) -> 0 | L27: =SUMIFS(Pagamentos!$E:$E,Pagamentos!$F:$F,TRUE,Pagamentos!$C:$C,$C27,Pagamentos!$D:$D,L$2) -> 0 | ... P27: =SUMIFS(Pagamentos!$E:$E,Pagamentos!$F:$F,TRUE,Pagamentos!$C:$C,$C27,Pagamentos!$D:$D,P$2) -> 0 | Q27: -1 | R27: =IF(Q27="","",((SUM(E27:P27)-$S$2)/20)+Q27) -> -3 | S27: =IFERROR(__xludf.DUMMYFUNCTION("SPARKLINE(SUM(E27:P27),{""charttype"",""bar"";""max"",$S$2})"),"")
B28: {=IFERROR(INDEX(#REF!,MATCH(C28,#REF!,0)),"")} | C28: =IFERROR(__xludf.DUMMYFUNCTION("""COMPUTED_VALUE"""),"Mina") -> Mina | D28: =IFERROR(__xludf.DUMMYFUNCTION("""COMPUTED_VALUE"""),"Kleber Pacheco Mina") -> Kleber Pacheco Mina | E28: =SUMIFS(Pagamentos!$E:$E,Pagamentos!$F:$F,TRUE,Pagamentos!$C:$C,$C28,Pagamentos!$D:$D,E$2) -> 0 | F28: =SUMIFS(Pagamentos!$E:$E,Pagamentos!$F:$F,TRUE,Pagamentos!$C:$C,$C28,Pagamentos!$D:$D,F$2) -> 0 | G28: =SUMIFS(Pagamentos!$E:$E,Pagamentos!$F:$F,TRUE,Pagamentos!$C:$C,$C28,Pagamentos!$D:$D,G$2) -> 60 | H28: =SUMIFS(Pagamentos!$E:$E,Pagamentos!$F:$F,TRUE,Pagamentos!$C:$C,$C28,Pagamentos!$D:$D,H$2) -> 0 | I28: =SUMIFS(Pagamentos!$E:$E,Pagamentos!$F:$F,TRUE,Pagamentos!$C:$C,$C28,Pagamentos!$D:$D,I$2) -> 0 | J28: =SUMIFS(Pagamentos!$E:$E,Pagamentos!$F:$F,TRUE,Pagamentos!$C:$C,$C28,Pagamentos!$D:$D,J$2) -> 80 | K28: =SUMIFS(Pagamentos!$E:$E,Pagamentos!$F:$F,TRUE,Pagamentos!$C:$C,$C28,Pagamentos!$D:$D,K$2) -> 0 | L28: =SUMIFS(Pagamentos!$E:$E,Pagamentos!$F:$F,TRUE,Pagamentos!$C:$C,$C28,Pagamentos!$D:$D,L$2) -> 0 | ... P28: =SUMIFS(Pagamentos!$E:$E,Pagamentos!$F:$F,TRUE,Pagamentos!$C:$C,$C28,Pagamentos!$D:$D,P$2) -> 0 | Q28: 0 | R28: =IF(Q28="","",((SUM(E28:P28)-$S$2)/20)+Q28) -> -1 | S28: =IFERROR(__xludf.DUMMYFUNCTION("SPARKLINE(SUM(E28:P28),{""charttype"",""bar"";""max"",$S$2})"),"")
B29: {=IFERROR(INDEX(#REF!,MATCH(C29,#REF!,0)),"")} | C29: =IFERROR(__xludf.DUMMYFUNCTION("""COMPUTED_VALUE"""),"Mithel") -> Mithel | D29: =IFERROR(__xludf.DUMMYFUNCTION("""COMPUTED_VALUE"""),"Mithel Evergisto de Lima") -> Mithel Evergisto de Lima | E29: =SUMIFS(Pagamentos!$E:$E,Pagamentos!$F:$F,TRUE,Pagamentos!$C:$C,$C29,Pagamentos!$D:$D,E$2) -> 0 | F29: =SUMIFS(Pagamentos!$E:$E,Pagamentos!$F:$F,TRUE,Pagamentos!$C:$C,$C29,Pagamentos!$D:$D,F$2) -> 0 | G29: =SUMIFS(Pagamentos!$E:$E,Pagamentos!$F:$F,TRUE,Pagamentos!$C:$C,$C29,Pagamentos!$D:$D,G$2) -> 100 | H29: =SUMIFS(Pagamentos!$E:$E,Pagamentos!$F:$F,TRUE,Pagamentos!$C:$C,$C29,Pagamentos!$D:$D,H$2) -> 0 | I29: =SUMIFS(Pagamentos!$E:$E,Pagamentos!$F:$F,TRUE,Pagamentos!$C:$C,$C29,Pagamentos!$D:$D,I$2) -> 0 | J29: =SUMIFS(Pagamentos!$E:$E,Pagamentos!$F:$F,TRUE,Pagamentos!$C:$C,$C29,Pagamentos!$D:$D,J$2) -> 0 | K29: =SUMIFS(Pagamentos!$E:$E,Pagamentos!$F:$F,TRUE,Pagamentos!$C:$C,$C29,Pagamentos!$D:$D,K$2) -> 0 | L29: =SUMIFS(Pagamentos!$E:$E,Pagamentos!$F:$F,TRUE,Pagamentos!$C:$C,$C29,Pagamentos!$D:$D,L$2) -> 0 | ... P29: =SUMIFS(Pagamentos!$E:$E,Pagamentos!$F:$F,TRUE,Pagamentos!$C:$C,$C29,Pagamentos!$D:$D,P$2) -> 0 | Q29: 0 | R29: =IF(Q29="","",((SUM(E29:P29)-$S$2)/20)+Q29) -> -3 | S29: =IFERROR(__xludf.DUMMYFUNCTION("SPARKLINE(SUM(E29:P29),{""charttype"",""bar"";""max"",$S$2})"),"")
B30: {=IFERROR(INDEX(#REF!,MATCH(C30,#REF!,0)),"")} | C30: =IFERROR(__xludf.DUMMYFUNCTION("""COMPUTED_VALUE"""),"Natayan") -> Natayan | D30: =IFERROR(__xludf.DUMMYFUNCTION("""COMPUTED_VALUE"""),"Raphael Natayan Nilsen") -> Raphael Natayan Nilsen | E30: =SUMIFS(Pagamentos!$E:$E,Pagamentos!$F:$F,TRUE,Pagamentos!$C:$C,$C30,Pagamentos!$D:$D,E$2) -> 40 | F30: =SUMIFS(Pagamentos!$E:$E,Pagamentos!$F:$F,TRUE,Pagamentos!$C:$C,$C30,Pagamentos!$D:$D,F$2) -> 0 | G30: =SUMIFS(Pagamentos!$E:$E,Pagamentos!$F:$F,TRUE,Pagamentos!$C:$C,$C30,Pagamentos!$D:$D,G$2) -> 20 | H30: =SUMIFS(Pagamentos!$E:$E,Pagamentos!$F:$F,TRUE,Pagamentos!$C:$C,$C30,Pagamentos!$D:$D,H$2) -> 20 | I30: =SUMIFS(Pagamentos!$E:$E,Pagamentos!$F:$F,TRUE,Pagamentos!$C:$C,$C30,Pagamentos!$D:$D,I$2) -> 20 | J30: =SUMIFS(Pagamentos!$E:$E,Pagamentos!$F:$F,TRUE,Pagamentos!$C:$C,$C30,Pagamentos!$D:$D,J$2) -> 20 | K30: =SUMIFS(Pagamentos!$E:$E,Pagamentos!$F:$F,TRUE,Pagamentos!$C:$C,$C30,Pagamentos!$D:$D,K$2) -> 20 | L30: =SUMIFS(Pagamentos!$E:$E,Pagamentos!$F:$F,TRUE,Pagamentos!$C:$C,$C30,Pagamentos!$D:$D,L$2) -> 0 | ... P30: =SUMIFS(Pagamentos!$E:$E,Pagamentos!$F:$F,TRUE,Pagamentos!$C:$C,$C30,Pagamentos!$D:$D,P$2) -> 0 | Q30: 0 | R30: =IF(Q30="","",((SUM(E30:P30)-$S$2)/20)+Q30) -> -1 | S30: =IFERROR(__xludf.DUMMYFUNCTION("SPARKLINE(SUM(E30:P30),{""charttype"",""bar"";""max"",$S$2})"),"")
B31: {=IFERROR(INDEX(#REF!,MATCH(C31,#REF!,0)),"")} | C31: =IFERROR(__xludf.DUMMYFUNCTION("""COMPUTED_VALUE"""),"Nery") -> Nery | D31: =IFERROR(__xludf.DUMMYFUNCTION("""COMPUTED_VALUE"""),"Gabriel Nery Cristiano ") -> Gabriel Nery Cristiano | E31: =SUMIFS(Pagamentos!$E:$E,Pagamentos!$F:$F,TRUE,Pagamentos!$C:$C,$C31,Pagamentos!$D:$D,E$2) -> 0 | F31: =SUMIFS(Pagamentos!$E:$E,Pagamentos!$F:$F,TRUE,Pagamentos!$C:$C,$C31,Pagamentos!$D:$D,F$2) -> 0 | G31: =SUMIFS(Pagamentos!$E:$E,Pagamentos!$F:$F,TRUE,Pagamentos!$C:$C,$C31,Pagamentos!$D:$D,G$2) -> 0 | H31: =SUMIFS(Pagamentos!$E:$E,Pagamentos!$F:$F,TRUE,Pagamentos!$C:$C,$C31,Pagamentos!$D:$D,H$2) -> 0 | I31: =SUMIFS(Pagamentos!$E:$E,Pagamentos!$F:$F,TRUE,Pagamentos!$C:$C,$C31,Pagamentos!$D:$D,I$2) -> 80 | J31: =SUMIFS(Pagamentos!$E:$E,Pagamentos!$F:$F,TRUE,Pagamentos!$C:$C,$C31,Pagamentos!$D:$D,J$2) -> 40 | K31: =SUMIFS(Pagamentos!$E:$E,Pagamentos!$F:$F,TRUE,Pagamentos!$C:$C,$C31,Pagamentos!$D:$D,K$2) -> 20 | L31: =SUMIFS(Pagamentos!$E:$E,Pagamentos!$F:$F,TRUE,Pagamentos!$C:$C,$C31,Pagamentos!$D:$D,L$2) -> 0 | ... P31: =SUMIFS(Pagamentos!$E:$E,Pagamentos!$F:$F,TRUE,Pagamentos!$C:$C,$C31,Pagamentos!$D:$D,P$2) -> 0 | Q31: 0 | R31: =IF(Q31="","",((SUM(E31:P31)-$S$2)/20)+Q31) -> -1 | S31: =IFERROR(__xludf.DUMMYFUNCTION("SPARKLINE(SUM(E31:P31),{""charttype"",""bar"";""max"",$S$2})"),"")
B32: {=IFERROR(INDEX(#REF!,MATCH(C32,#REF!,0)),"")} | C32: =IFERROR(__xludf.DUMMYFUNCTION("""COMPUTED_VALUE"""),"Oliveira") -> Oliveira | D32: =IFERROR(__xludf.DUMMYFUNCTION("""COMPUTED_VALUE"""),"Marcelo luiz de Oliveira") -> Marcelo luiz de Oliveira | E32: =SUMIFS(Pagamentos!$E:$E,Pagamentos!$F:$F,TRUE,Pagamentos!$C:$C,$C32,Pagamentos!$D:$D,E$2) -> 0 | F32: =SUMIFS(Pagamentos!$E:$E,Pagamentos!$F:$F,TRUE,Pagamentos!$C:$C,$C32,Pagamentos!$D:$D,F$2) -> 0 | G32: =SUMIFS(Pagamentos!$E:$E,Pagamentos!$F:$F,TRUE,Pagamentos!$C:$C,$C32,Pagamentos!$D:$D,G$2) -> 40 | H32: =SUMIFS(Pagamentos!$E:$E,Pagamentos!$F:$F,TRUE,Pagamentos!$C:$C,$C32,Pagamentos!$D:$D,H$2) -> 0 | I32: =SUMIFS(Pagamentos!$E:$E,Pagamentos!$F:$F,TRUE,Pagamentos!$C:$C,$C32,Pagamentos!$D:$D,I$2) -> 80 | J32: =SUMIFS(Pagamentos!$E:$E,Pagamentos!$F:$F,TRUE,Pagamentos!$C:$C,$C32,Pagamentos!$D:$D,J$2) -> 0 | K32: =SUMIFS(Pagamentos!$E:$E,Pagamentos!$F:$F,TRUE,Pagamentos!$C:$C,$C32,Pagamentos!$D:$D,K$2) -> 20 | L32: =SUMIFS(Pagamentos!$E:$E,Pagamentos!$F:$F,TRUE,Pagamentos!$C:$C,$C32,Pagamentos!$D:$D,L$2) -> 0 | ... P32: =SUMIFS(Pagamentos!$E:$E,Pagamentos!$F:$F,TRUE,Pagamentos!$C:$C,$C32,Pagamentos!$D:$D,P$2) -> 0 | Q32: -1 | R32: =IF(Q32="","",((SUM(E32:P32)-$S$2)/20)+Q32) -> -2 | S32: =IFERROR(__xludf.DUMMYFUNCTION("SPARKLINE(SUM(E32:P32),{""charttype"",""bar"";""max"",$S$2})"),"")
B33: {=IFERROR(INDEX(#REF!,MATCH(C33,#REF!,0)),"")} | C33: =IFERROR(__xludf.DUMMYFUNCTION("""COMPUTED_VALUE"""),"Ozol") -> Ozol | D33: =IFERROR(__xludf.DUMMYFUNCTION("""COMPUTED_VALUE"""),"Guilherme Ozol de Assunção ") -> Guilherme Ozol de Assunção | E33: =SUMIFS(Pagamentos!$E:$E,Pagamentos!$F:$F,TRUE,Pagamentos!$C:$C,$C33,Pagamentos!$D:$D,E$2) -> 0 | F33: =SUMIFS(Pagamentos!$E:$E,Pagamentos!$F:$F,TRUE,Pagamentos!$C:$C,$C33,Pagamentos!$D:$D,F$2) -> 0 | G33: =SUMIFS(Pagamentos!$E:$E,Pagamentos!$F:$F,TRUE,Pagamentos!$C:$C,$C33,Pagamentos!$D:$D,G$2) -> 60 | H33: =SUMIFS(Pagamentos!$E:$E,Pagamentos!$F:$F,TRUE,Pagamentos!$C:$C,$C33,Pagamentos!$D:$D,H$2) -> 0 | I33: =SUMIFS(Pagamentos!$E:$E,Pagamentos!$F:$F,TRUE,Pagamentos!$C:$C,$C33,Pagamentos!$D:$D,I$2) -> 0 | J33: =SUMIFS(Pagamentos!$E:$E,Pagamentos!$F:$F,TRUE,Pagamentos!$C:$C,$C33,Pagamentos!$D:$D,J$2) -> 0 | K33: =SUMIFS(Pagamentos!$E:$E,Pagamentos!$F:$F,TRUE,Pagamentos!$C:$C,$C33,Pagamentos!$D:$D,K$2) -> 0 | L33: =SUMIFS(Pagamentos!$E:$E,Pagamentos!$F:$F,TRUE,Pagamentos!$C:$C,$C33,Pagamentos!$D:$D,L$2) -> 0 | ... P33: =SUMIFS(Pagamentos!$E:$E,Pagamentos!$F:$F,TRUE,Pagamentos!$C:$C,$C33,Pagamentos!$D:$D,P$2) -> 0 | Q33: 0 | R33: =IF(Q33="","",((SUM(E33:P33)-$S$2)/20)+Q33) -> -5 | S33: =IFERROR(__xludf.DUMMYFUNCTION("SPARKLINE(SUM(E33:P33),{""charttype"",""bar"";""max"",$S$2})"),"")
B34: {=IFERROR(INDEX(#REF!,MATCH(C34,#REF!,0)),"")} | C34: =IFERROR(__xludf.DUMMYFUNCTION("""COMPUTED_VALUE"""),"Pereira") -> Pereira | D34: =IFERROR(__xludf.DUMMYFUNCTION("""COMPUTED_VALUE"""),"Emerson Pereira") -> Emerson Pereira | E34: =SUMIFS(Pagamentos!$E:$E,Pagamentos!$F:$F,TRUE,Pagamentos!$C:$C,$C34,Pagamentos!$D:$D,E$2) -> 0 | F34: =SUMIFS(Pagamentos!$E:$E,Pagamentos!$F:$F,TRUE,Pagamentos!$C:$C,$C34,Pagamentos!$D:$D,F$2) -> 80 | G34: =SUMIFS(Pagamentos!$E:$E,Pagamentos!$F:$F,TRUE,Pagamentos!$C:$C,$C34,Pagamentos!$D:$D,G$2) -> 0 | H34: =SUMIFS(Pagamentos!$E:$E,Pagamentos!$F:$F,TRUE,Pagamentos!$C:$C,$C34,Pagamentos!$D:$D,H$2) -> 0 | I34: =SUMIFS(Pagamentos!$E:$E,Pagamentos!$F:$F,TRUE,Pagamentos!$C:$C,$C34,Pagamentos!$D:$D,I$2) -> 0 | J34: =SUMIFS(Pagamentos!$E:$E,Pagamentos!$F:$F,TRUE,Pagamentos!$C:$C,$C34,Pagamentos!$D:$D,J$2) -> 0 | K34: =SUMIFS(Pagamentos!$E:$E,Pagamentos!$F:$F,TRUE,Pagamentos!$C:$C,$C34,Pagamentos!$D:$D,K$2) -> 180 | L34: =SUMIFS(Pagamentos!$E:$E,Pagamentos!$F:$F,TRUE,Pagamentos!$C:$C,$C34,Pagamentos!$D:$D,L$2) -> 0 | ... P34: =SUMIFS(Pagamentos!$E:$E,Pagamentos!$F:$F,TRUE,Pagamentos!$C:$C,$C34,Pagamentos!$D:$D,P$2) -> 0 | Q34: 0 | R34: =IF(Q34="","",((SUM(E34:P34)-$S$2)/20)+Q34) -> 5 | S34: =IFERROR(__xludf.DUMMYFUNCTION("SPARKLINE(SUM(E34:P34),{""charttype"",""bar"";""max"",$S$2})"),"")
B35: {=IFERROR(INDEX(#REF!,MATCH(C35,#REF!,0)),"")} | C35: =IFERROR(__xludf.DUMMYFUNCTION("""COMPUTED_VALUE"""),"Ravache") -> Ravache | D35: =IFERROR(__xludf.DUMMYFUNCTION("""COMPUTED_VALUE"""),"Caio Passold Ravache") -> Caio Passold Ravache | E35: =SUMIFS(Pagamentos!$E:$E,Pagamentos!$F:$F,TRUE,Pagamentos!$C:$C,$C35,Pagamentos!$D:$D,E$2) -> 0 | F35: =SUMIFS(Pagamentos!$E:$E,Pagamentos!$F:$F,TRUE,Pagamentos!$C:$C,$C35,Pagamentos!$D:$D,F$2) -> 0 | G35: =SUMIFS(Pagamentos!$E:$E,Pagamentos!$F:$F,TRUE,Pagamentos!$C:$C,$C35,Pagamentos!$D:$D,G$2) -> 0 | H35: =SUMIFS(Pagamentos!$E:$E,Pagamentos!$F:$F,TRUE,Pagamentos!$C:$C,$C35,Pagamentos!$D:$D,H$2) -> 0 | I35: =SUMIFS(Pagamentos!$E:$E,Pagamentos!$F:$F,TRUE,Pagamentos!$C:$C,$C35,Pagamentos!$D:$D,I$2) -> 0 | J35: =SUMIFS(Pagamentos!$E:$E,Pagamentos!$F:$F,TRUE,Pagamentos!$C:$C,$C35,Pagamentos!$D:$D,J$2) -> 0 | K35: =SUMIFS(Pagamentos!$E:$E,Pagamentos!$F:$F,TRUE,Pagamentos!$C:$C,$C35,Pagamentos!$D:$D,K$2) -> 0 | L35: =SUMIFS(Pagamentos!$E:$E,Pagamentos!$F:$F,TRUE,Pagamentos!$C:$C,$C35,Pagamentos!$D:$D,L$2) -> 0 | ... P35: =SUMIFS(Pagamentos!$E:$E,Pagamentos!$F:$F,TRUE,Pagamentos!$C:$C,$C35,Pagamentos!$D:$D,P$2) -> 0 | Q35: 0 | R35: =IF(Q35="","",((SUM(E35:P35)-$S$2)/20)+Q35) -> -8 | S35: =IFERROR(__xludf.DUMMYFUNCTION("SPARKLINE(SUM(E35:P35),{""charttype"",""bar"";""max"",$S$2})"),"")
B36: {=IFERROR(INDEX(#REF!,MATCH(C36,#REF!,0)),"")} | C36: =IFERROR(__xludf.DUMMYFUNCTION("""COMPUTED_VALUE"""),"Santana") -> Santana | D36: =IFERROR(__xludf.DUMMYFUNCTION("""COMPUTED_VALUE"""),"Michele Santana Quint") -> Michele Santana Quint | E36: =SUMIFS(Pagamentos!$E:$E,Pagamentos!$F:$F,TRUE,Pagamentos!$C:$C,$C36,Pagamentos!$D:$D,E$2) -> 0 | F36: =SUMIFS(Pagamentos!$E:$E,Pagamentos!$F:$F,TRUE,Pagamentos!$C:$C,$C36,Pagamentos!$D:$D,F$2) -> 0 | G36: =SUMIFS(Pagamentos!$E:$E,Pagamentos!$F:$F,TRUE,Pagamentos!$C:$C,$C36,Pagamentos!$D:$D,G$2) -> 60 | H36: =SUMIFS(Pagamentos!$E:$E,Pagamentos!$F:$F,TRUE,Pagamentos!$C:$C,$C36,Pagamentos!$D:$D,H$2) -> 0 | I36: =SUMIFS(Pagamentos!$E:$E,Pagamentos!$F:$F,TRUE,Pagamentos!$C:$C,$C36,Pagamentos!$D:$D,I$2) -> 0 | J36: =SUMIFS(Pagamentos!$E:$E,Pagamentos!$F:$F,TRUE,Pagamentos!$C:$C,$C36,Pagamentos!$D:$D,J$2) -> 0 | K36: =SUMIFS(Pagamentos!$E:$E,Pagamentos!$F:$F,TRUE,Pagamentos!$C:$C,$C36,Pagamentos!$D:$D,K$2) -> 0 | L36: =SUMIFS(Pagamentos!$E:$E,Pagamentos!$F:$F,TRUE,Pagamentos!$C:$C,$C36,Pagamentos!$D:$D,L$2) -> 0 | ... P36: =SUMIFS(Pagamentos!$E:$E,Pagamentos!$F:$F,TRUE,Pagamentos!$C:$C,$C36,Pagamentos!$D:$D,P$2) -> 0 | Q36: 0 | R36: =IF(Q36="","",((SUM(E36:P36)-$S$2)/20)+Q36) -> -5 | S36: =IFERROR(__xludf.DUMMYFUNCTION("SPARKLINE(SUM(E36:P36),{""charttype"",""bar"";""max"",$S$2})"),"")
B37: {=IFERROR(INDEX(#REF!,MATCH(C37,#REF!,0)),"")} | C37: =IFERROR(__xludf.DUMMYFUNCTION("""COMPUTED_VALUE"""),"Sardá") -> Sardá | D37: =IFERROR(__xludf.DUMMYFUNCTION("""COMPUTED_VALUE"""),"Julia da Silva Sardá ") -> Julia da Silva Sardá | E37: =SUMIFS(Pagamentos!$E:$E,Pagamentos!$F:$F,TRUE,Pagamentos!$C:$C,$C37,Pagamentos!$D:$D,E$2) -> 0 | F37: =SUMIFS(Pagamentos!$E:$E,Pagamentos!$F:$F,TRUE,Pagamentos!$C:$C,$C37,Pagamentos!$D:$D,F$2) -> 0 | G37: =SUMIFS(Pagamentos!$E:$E,Pagamentos!$F:$F,TRUE,Pagamentos!$C:$C,$C37,Pagamentos!$D:$D,G$2) -> 60 | H37: =SUMIFS(Pagamentos!$E:$E,Pagamentos!$F:$F,TRUE,Pagamentos!$C:$C,$C37,Pagamentos!$D:$D,H$2) -> 20 | I37: =SUMIFS(Pagamentos!$E:$E,Pagamentos!$F:$F,TRUE,Pagamentos!$C:$C,$C37,Pagamentos!$D:$D,I$2) -> 0 | J37: =SUMIFS(Pagamentos!$E:$E,Pagamentos!$F:$F,TRUE,Pagamentos!$C:$C,$C37,Pagamentos!$D:$D,J$2) -> 0 | K37: =SUMIFS(Pagamentos!$E:$E,Pagamentos!$F:$F,TRUE,Pagamentos!$C:$C,$C37,Pagamentos!$D:$D,K$2) -> 0 | L37: =SUMIFS(Pagamentos!$E:$E,Pagamentos!$F:$F,TRUE,Pagamentos!$C:$C,$C37,Pagamentos!$D:$D,L$2) -> 0 | ... P37: =SUMIFS(Pagamentos!$E:$E,Pagamentos!$F:$F,TRUE,Pagamentos!$C:$C,$C37,Pagamentos!$D:$D,P$2) -> 0 | Q37: 0 | R37: =IF(Q37="","",((SUM(E37:P37)-$S$2)/20)+Q37) -> -4 | S37: =IFERROR(__xludf.DUMMYFUNCTION("SPARKLINE(SUM(E37:P37),{""charttype"",""bar"";""max"",$S$2})"),"")
B38: {=IFERROR(INDEX(#REF!,MATCH(C38,#REF!,0)),"")} | C38: =IFERROR(__xludf.DUMMYFUNCTION("""COMPUTED_VALUE"""),"Schmitt") -> Schmitt | D38: =IFERROR(__xludf.DUMMYFUNCTION("""COMPUTED_VALUE"""),"André Luiz Schmitt") -> André Luiz Schmitt | E38: =SUMIFS(Pagamentos!$E:$E,Pagamentos!$F:$F,TRUE,Pagamentos!$C:$C,$C38,Pagamentos!$D:$D,E$2) -> 0 | F38: =SUMIFS(Pagamentos!$E:$E,Pagamentos!$F:$F,TRUE,Pagamentos!$C:$C,$C38,Pagamentos!$D:$D,F$2) -> 0 | G38: =SUMIFS(Pagamentos!$E:$E,Pagamentos!$F:$F,TRUE,Pagamentos!$C:$C,$C38,Pagamentos!$D:$D,G$2) -> 100 | H38: =SUMIFS(Pagamentos!$E:$E,Pagamentos!$F:$F,TRUE,Pagamentos!$C:$C,$C38,Pagamentos!$D:$D,H$2) -> 0 | I38: =SUMIFS(Pagamentos!$E:$E,Pagamentos!$F:$F,TRUE,Pagamentos!$C:$C,$C38,Pagamentos!$D:$D,I$2) -> 0 | J38: =SUMIFS(Pagamentos!$E:$E,Pagamentos!$F:$F,TRUE,Pagamentos!$C:$C,$C38,Pagamentos!$D:$D,J$2) -> 0 | K38: =SUMIFS(Pagamentos!$E:$E,Pagamentos!$F:$F,TRUE,Pagamentos!$C:$C,$C38,Pagamentos!$D:$D,K$2) -> 0 | L38: =SUMIFS(Pagamentos!$E:$E,Pagamentos!$F:$F,TRUE,Pagamentos!$C:$C,$C38,Pagamentos!$D:$D,L$2) -> 0 | ... P38: =SUMIFS(Pagamentos!$E:$E,Pagamentos!$F:$F,TRUE,Pagamentos!$C:$C,$C38,Pagamentos!$D:$D,P$2) -> 0 | Q38: -1 | R38: =IF(Q38="","",((SUM(E38:P38)-$S$2)/20)+Q38) -> -4 | S38: =IFERROR(__xludf.DUMMYFUNCTION("SPARKLINE(SUM(E38:P38),{""charttype"",""bar"";""max"",$S$2})"),"")
B39: {=IFERROR(INDEX(#REF!,MATCH(C39,#REF!,0)),"")} | C39: =IFERROR(__xludf.DUMMYFUNCTION("""COMPUTED_VALUE"""),"Spotti") -> Spotti | D39: =IFERROR(__xludf.DUMMYFUNCTION("""COMPUTED_VALUE"""),"Kleber Spotti Rodrigues") -> Kleber Spotti Rodrigues | E39: =SUMIFS(Pagamentos!$E:$E,Pagamentos!$F:$F,TRUE,Pagamentos!$C:$C,$C39,Pagamentos!$D:$D,E$2) -> 0 | F39: =SUMIFS(Pagamentos!$E:$E,Pagamentos!$F:$F,TRUE,Pagamentos!$C:$C,$C39,Pagamentos!$D:$D,F$2) -> 0 | G39: =SUMIFS(Pagamentos!$E:$E,Pagamentos!$F:$F,TRUE,Pagamentos!$C:$C,$C39,Pagamentos!$D:$D,G$2) -> 100 | H39: =SUMIFS(Pagamentos!$E:$E,Pagamentos!$F:$F,TRUE,Pagamentos!$C:$C,$C39,Pagamentos!$D:$D,H$2) -> 0 | I39: =SUMIFS(Pagamentos!$E:$E,Pagamentos!$F:$F,TRUE,Pagamentos!$C:$C,$C39,Pagamentos!$D:$D,I$2) -> 0 | J39: =SUMIFS(Pagamentos!$E:$E,Pagamentos!$F:$F,TRUE,Pagamentos!$C:$C,$C39,Pagamentos!$D:$D,J$2) -> 0 | K39: =SUMIFS(Pagamentos!$E:$E,Pagamentos!$F:$F,TRUE,Pagamentos!$C:$C,$C39,Pagamentos!$D:$D,K$2) -> 0 | L39: =SUMIFS(Pagamentos!$E:$E,Pagamentos!$F:$F,TRUE,Pagamentos!$C:$C,$C39,Pagamentos!$D:$D,L$2) -> 100 | ... P39: =SUMIFS(Pagamentos!$E:$E,Pagamentos!$F:$F,TRUE,Pagamentos!$C:$C,$C39,Pagamentos!$D:$D,P$2) -> 0 | Q39: 2 | R39: =IF(Q39="","",((SUM(E39:P39)-$S$2)/20)+Q39) -> 4 | S39: =IFERROR(__xludf.DUMMYFUNCTION("SPARKLINE(SUM(E39:P39),{""charttype"",""bar"";""max"",$S$2})"),"")
B40: {=IFERROR(INDEX(#REF!,MATCH(C40,#REF!,0)),"")} | C40: =IFERROR(__xludf.DUMMYFUNCTION("""COMPUTED_VALUE"""),"Alves") -> Alves | D40: =IFERROR(__xludf.DUMMYFUNCTION("""COMPUTED_VALUE"""),"Uelder Alves Da Costa") -> Uelder Alves Da Costa | E40: =SUMIFS(Pagamentos!$E:$E,Pagamentos!$F:$F,TRUE,Pagamentos!$C:$C,$C40,Pagamentos!$D:$D,E$2) -> 0 | F40: =SUMIFS(Pagamentos!$E:$E,Pagamentos!$F:$F,TRUE,Pagamentos!$C:$C,$C40,Pagamentos!$D:$D,F$2) -> 240 | G40: =SUMIFS(Pagamentos!$E:$E,Pagamentos!$F:$F,TRUE,Pagamentos!$C:$C,$C40,Pagamentos!$D:$D,G$2) -> 0 | H40: =SUMIFS(Pagamentos!$E:$E,Pagamentos!$F:$F,TRUE,Pagamentos!$C:$C,$C40,Pagamentos!$D:$D,H$2) -> 0 | I40: =SUMIFS(Pagamentos!$E:$E,Pagamentos!$F:$F,TRUE,Pagamentos!$C:$C,$C40,Pagamentos!$D:$D,I$2) -> 0 | J40: =SUMIFS(Pagamentos!$E:$E,Pagamentos!$F:$F,TRUE,Pagamentos!$C:$C,$C40,Pagamentos!$D:$D,J$2) -> 0 | K40: =SUMIFS(Pagamentos!$E:$E,Pagamentos!$F:$F,TRUE,Pagamentos!$C:$C,$C40,Pagamentos!$D:$D,K$2) -> 0 | L40: =SUMIFS(Pagamentos!$E:$E,Pagamentos!$F:$F,TRUE,Pagamentos!$C:$C,$C40,Pagamentos!$D:$D,L$2) -> 0 | ... P40: =SUMIFS(Pagamentos!$E:$E,Pagamentos!$F:$F,TRUE,Pagamentos!$C:$C,$C40,Pagamentos!$D:$D,P$2) -> 0 | Q40: 0 | R40: =IF(Q40="","",((SUM(E40:P40)-$S$2)/20)+Q40) -> 4 | S40: =IFERROR(__xludf.DUMMYFUNCTION("SPARKLINE(SUM(E40:P40),{""charttype"",""bar"";""max"",$S$2})"),"")
...

Sheet Lançamentos
B1: Descritivo | C1: Despesa | D1: Receita | E1: Valor | F1: Data | G1: Mês | H1: Mês
B2: Taxa "Cesta de Relacionamento" Sicred | C2: Tarifas Banco | E2: 35 | F2: 46042 | G2: =IF(F2="","",MONTH(F2)) -> 1 | H2: {=IF(F2="","",INDEX(Cripto!$A$1:$A$12,G2))} -> Janeiro
B3: Sandro Martins (Copo B4 / FECABOM) | C3: Outros | E3: 50 | F3: 46048 | G3: =IF(F3="","",MONTH(F3)) -> 1 | H3: {=IF(F3="","",INDEX(Cripto!$A$1:$A$12,G3))} -> Janeiro
B4: Tarifas Caixa Economica Federal | C4: Tarifas Banco | E4: 0.17 | F4: 46053 | G4: =IF(F4="","",MONTH(F4)) -> 1 | H4: {=IF(F4="","",INDEX(Cripto!$A$1:$A$12,G4))} -> Janeiro
B5: Rendimentos Caixa Economica Federal | D5: Rendimentos | E5: =0.3+0.1 -> 0.4 | F5: 46053 | G5: =IF(F5="","",MONTH(F5)) -> 1 | H5: {=IF(F5="","",INDEX(Cripto!$A$1:$A$12,G5))} -> Janeiro
B6: Certificado Digital | C6: Outros | E6: 170 | F6: 46062 | G6: =IF(F6="","",MONTH(F6)) -> 2 | H6: {=IF(F6="","",INDEX(Cripto!$A$1:$A$12,G6))} -> Fevereiro
B7: Brinde Reunião Comando (Camila C Soares) | C7: Presentes | E7: 47.61 | F7: 46073 | G7: =IF(F7="","",MONTH(F7)) -> 2 | H7: {=IF(F7="","",INDEX(Cripto!$A$1:$A$12,G7))} -> Fevereiro
B8: Taxa "Cesta de Relacionamento" Sicred | C8: Tarifas Banco | E8: 35 | F8: 46073 | G8: =IF(F8="","",MONTH(F8)) -> 2 | H8: {=IF(F8="","",INDEX(Cripto!$A$1:$A$12,G8))} -> Fevereiro
B9: Lancheira aniversários Compra 1 | C9: Presentes | E9: 1945 | F9: 46076 | G9: =IF(F9="","",MONTH(F9)) -> 2 | H9: {=IF(F9="","",INDEX(Cripto!$A$1:$A$12,G9))} -> Fevereiro
B10: Lancheira aniversários Compra 2 | C10: Presentes | E10: 775.8 | F10: 46076 | G10: =IF(F10="","",MONTH(F10)) -> 2 | H10: {=IF(F10="","",INDEX(Cripto!$A$1:$A$12,G10))} -> Fevereiro
B11: Tarifas Caixa Economica Federal | C11: Tarifas Banco | E11: 0.17 | F11: 46081 | G11: =IF(F11="","",MONTH(F11)) -> 2 | H11: {=IF(F11="","",INDEX(Cripto!$A$1:$A$12,G11))} -> Fevereiro
B12: Rendimentos Caixa Economica Federal | D12: Rendimentos | E12: =SUM(0.14+0.4) -> 0.54 | F12: 46081 | G12: =IF(F12="","",MONTH(F12)) -> 2 | H12: {=IF(F12="","",INDEX(Cripto!$A$1:$A$12,G12))} -> Fevereiro
B13: Estampa das lancheiras (Adriano Lima) | C13: Presentes | E13: 800 | F13: 46093 | G13: =IF(F13="","",MONTH(F13)) -> 3 | H13: {=IF(F13="","",INDEX(Cripto!$A$1:$A$12,G13))} -> Março
B14: Taxa "Cesta de Relacionamento" Sicred | C14: Tarifas Banco | E14: 35 | F14: 46101 | G14: =IF(F14="","",MONTH(F14)) -> 3 | H14: {=IF(F14="","",INDEX(Cripto!$A$1:$A$12,G14))} -> Março
B15: Tarifas Caixa Economica Federal | C15: Tarifas Banco | E15: 0.88 | F15: 46111 | G15: =IF(F15="","",MONTH(F15)) -> 3 | H15: {=IF(F15="","",INDEX(Cripto!$A$1:$A$12,G15))} -> Março
B16: Rendimentos Caixa Economica Federal | D16: Rendimentos | E16: 0.62 | F16: 46111 | G16: =IF(F16="","",MONTH(F16)) -> 3 | H16: {=IF(F16="","",INDEX(Cripto!$A$1:$A$12,G16))} -> Março
B17: Coffee Break Treinamento APH (João Valdeci Moraes) | C17: Treinamentos | E17: 240 | F17: 46125 | G17: =IF(F17="","",MONTH(F17)) -> 4 | H17: {=IF(F17="","",INDEX(Cripto!$A$1:$A$12,G17))} -> Abril
B18: Coffee Break Treinamento APH (Camila Soares) | C18: Treinamentos | E18: 132.08 | F18: 46125 | G18: =IF(F18="","",MONTH(F18)) -> 4 | H18: {=IF(F18="","",INDEX(Cripto!$A$1:$A$12,G18))} -> Abril
B19: Taxa "Cesta de Relacionamento" Sicred | C19: Tarifas Banco | E19: 35 | F19: 46132 | G19: =IF(F19="","",MONTH(F19)) -> 4 | H19: {=IF(F19="","",INDEX(Cripto!$A$1:$A$12,G19))} -> Abril
B20: Cartório (Gabriel F.Farias) | C20: Cartório ou Documentação em geral | E20: 193.67 | F20: 46136 | G20: =IF(F20="","",MONTH(F20)) -> 4 | H20: {=IF(F20="","",INDEX(Cripto!$A$1:$A$12,G20))} -> Abril
B21: Rendimentos Caixa Economica Federal | D21: Rendimentos | E21: 1.34 | F21: 46142 | G21: =IF(F21="","",MONTH(F21)) -> 4 | H21: {=IF(F21="","",INDEX(Cripto!$A$1:$A$12,G21))} -> Abril
B22: Taxa "Cesta de Relacionamento" Sicred | C22: Tarifas Banco | E22: 35 | F22: 46162 | G22: =IF(F22="","",MONTH(F22)) -> 5 | H22: {=IF(F22="","",INDEX(Cripto!$A$1:$A$12,G22))} -> Maio
B23: Rendimentos SICREDI | D23: Rendimentos | E23: 11.31 | F23: 46146 | G23: =IF(F23="","",MONTH(F23)) -> 5 | H23: {=IF(F23="","",INDEX(Cripto!$A$1:$A$12,G23))} -> Maio
B24: Rendimentos Caixa Economica Federal | D24: Rendimentos | E24: =0.1+0.02+0.1+0.03+0.41+0.14+0.4+0.08 -> 1.28 | F24: 46173 | G24: =IF(F24="","",MONTH(F24)) -> 5 | H24: {=IF(F24="","",INDEX(Cripto!$A$1:$A$12,G24))} -> Maio
B25: Jogo Copa do Mundo - Acompanhante (Linder) | D25: Rendimentos | E25: 25 | F25: 46184 | G25: =IF(F25="","",MONTH(F25)) -> 6 | H25: {=IF(F25="","",INDEX(Cripto!$A$1:$A$12,G25))} -> Junho
B26: Taxa de funcionamento PMSJ | C26: Cartório ou Documentação em geral | E26: 440.66 | F26: 46184 | G26: =IF(F26="","",MONTH(F26)) -> 6 | H26: {=IF(F26="","",INDEX(Cripto!$A$1:$A$12,G26))} -> Junho
B27: Certificado Digital (Safe2pay) | C27: Cartório ou Documentação em geral | E27: 184 | F27: 46184 | G27: =IF(F27="","",MONTH(F27)) -> 6 | H27: {=IF(F27="","",INDEX(Cripto!$A$1:$A$12,G27))} -> Junho
B28: jogo Copa do Mundo - Acompanhante (Antunes) | D28: Rendimentos | E28: 25 | F28: 46188 | G28: =IF(F28="","",MONTH(F28)) -> 6 | H28: {=IF(F28="","",INDEX(Cripto!$A$1:$A$12,G28))} -> Junho
B29: Jogo Copa do Mundo - Acompanhante (Humberto) | D29: Rendimentos | E29: 25 | F29: 46190 | G29: =IF(F29="","",MONTH(F29)) -> 6 | H29: {=IF(F29="","",INDEX(Cripto!$A$1:$A$12,G29))} -> Junho
B30: Decoração e descartaveis - Jogo Copa do Mundo (Yanka) | C30: Mercado | E30: 80.85 | F30: 46191 | G30: =IF(F30="","",MONTH(F30)) -> 6 | H30: {=IF(F30="","",INDEX(Cripto!$A$1:$A$12,G30))} -> Junho
B31: Mercado - Jogo Copa do Mundo (MundialMIX) | C31: Mercado | E31: 248.35 | F31: 46195 | G31: =IF(F31="","",MONTH(F31)) -> 6 | H31: {=IF(F31="","",INDEX(Cripto!$A$1:$A$12,G31))} -> Junho
B32: Mercado - Jogo Copa do Mundo (Yanka) | C32: Mercado | E32: 35.66 | F32: 46195 | G32: =IF(F32="","",MONTH(F32)) -> 6 | H32: {=IF(F32="","",INDEX(Cripto!$A$1:$A$12,G32))} -> Junho
B33: Taxa "Cesta de Relacionamento" Sicred | C33: Tarifas Banco | E33: 35 | F33: 46195 | G33: =IF(F33="","",MONTH(F33)) -> 6 | H33: {=IF(F33="","",INDEX(Cripto!$A$1:$A$12,G33))} -> Junho
B34: Pães - Jogo Copa do Mundo (Industria de Paes) | C34: Mercado | E34: 36 | F34: 46196 | G34: =IF(F34="","",MONTH(F34)) -> 6 | H34: {=IF(F34="","",INDEX(Cripto!$A$1:$A$12,G34))} -> Junho
B35: Jogo Copa do Mundo - Acompanhante (Kassandra) | D35: Rendimentos | E35: 25 | F35: 46197 | G35: =IF(F35="","",MONTH(F35)) -> 6 | H35: {=IF(F35="","",INDEX(Cripto!$A$1:$A$12,G35))} -> Junho
B36: Tarifas Caixa Economica Federal | C36: Tarifas Banco | E36: 0.71 | F36: 46203 | G36: =IF(F36="","",MONTH(F36)) -> 6 | H36: {=IF(F36="","",INDEX(Cripto!$A$1:$A$12,G36))} -> Junho
B37: Rendimentos Caixa Economica Federal | D37: Rendimentos | E37: =(0.1+0.03+0.1+0.03+0.41+0.14+0.4+0.14) -> 1.35 | F37: 46203 | G37: =IF(F37="","",MONTH(F37)) -> 6 | H37: {=IF(F37="","",INDEX(Cripto!$A$1:$A$12,G37))} -> Junho
B38: Coffee Break - Palestra (Kiko) | C38: Treinamentos | E38: 384 | F38: 46220 | G38: =IF(F38="","",MONTH(F38)) -> 7 | H38: {=IF(F38="","",INDEX(Cripto!$A$1:$A$12,G38))} -> Julho
B39: Taxa "Cesta de Relacionamento" Sicredi | C39: Tarifas Banco | E39: 35 | F39: 46223 | G39: =IF(F39="","",MONTH(F39)) -> 7 | H39: {=IF(F39="","",INDEX(Cripto!$A$1:$A$12,G39))} -> Julho
B40: Refri - Palestra (Yanka) | C40: Treinamentos | E40: 38.88 | F40: 46225 | G40: =IF(F40="","",MONTH(F40)) -> 7 | H40: {=IF(F40="","",INDEX(Cripto!$A$1:$A$12,G40))} -> Julho
...

Sheet Pagamentos
B1: Controle de Pagamento de Mensalidade
B2: Carimbo de data/hora | C2: Nome de Guerra | D2: Mês | E2: Valor | F2: Confirmo que todos os processos de conferência do pagamento foram efetuados
B3: 46061 | C3: Lourenço | D3: Janeiro | E3: 20 | F3: TRUE
B4: 46061 | C4: Luiz | D4: Janeiro | E4: 20 | F4: TRUE
B5: 46061 | C5: Yuri | D5: Janeiro | E5: 20 | F5: TRUE
B6: 46061 | C6: Antunes | D6: janeiro | E6: 20 | F6: TRUE
B7: 46061 | C7: Siqueira | D7: janeiro | E7: 20 | F7: TRUE
B8: 46061 | C8: Camila | D8: janeiro | E8: 20 | F8: TRUE
B9: 46061 | C9: Yanka | D9: janeiro | E9: 20 | F9: TRUE
B10: 46061 | C10: Martins | D10: janeiro | E10: 20 | F10: TRUE
B11: 46061 | C11: Natayan | D11: janeiro | E11: 40 | F11: TRUE
B12: 46061 | C12: Augusto | D12: janeiro | E12: 20 | F12: TRUE
B13: 46061 | C13: Nakata | D13: janeiro | E13: 40 | F13: TRUE
B14: 46061 | C14: Neumann | D14: janeiro | E14: 20 | F14: TRUE
... B227: 46240 | C227: Andréia M | D227: Agosto | E227: 20 | F227: TRUE
F228: FALSE
F229: FALSE
F230: FALSE
F231: FALSE
F232: FALSE
F233: FALSE
F234: FALSE
F235: FALSE
F236: FALSE
F237: FALSE
F238: FALSE
F239: FALSE
... F1279: FALSE
